Workbook
Name _DLX10.USE: #REF!
Name _DLX11.USE: acm!$A$2:$E$6
Name _DLX12.USE: cr!$A$2:$E$6
Name _DLX3344.USE: #REF!
Name _DLX399.USE: cbo_debt_lt!$A$2:$H$6
Name _DLX4.USE: ffr!$A$1:$C$5
Name _DLX482.USE: cbo_debt!$A$2:$CS$5
Name _DLX482.USE: cbo_deficit!$A$2:$CS$5
Name _DLX482.USE: cbo_deficit_gdp!$A$2:$CS$5
Name _DLX482.USE: cbo_interest!$A$2:$CS$5
Name _DLX482.USE: cbo_interest_gdp!$A$2:$CS$5
Name _DLX482.USE: cbo_ngdp!$A$2:$CS$5
Name _DLX482.USE: cbo_outlays!$A$2:$CS$5
Name _DLX482.USE: cbo_outlays_gdp!$A$2:$CS$5
Name _DLX482.USE: cbo_primary_deficit!$A$2:$CS$5
Name _DLX482.USE: cbo_primary_deficit_gdp!$A$2:$CS$5
Name _DLX482.USE: cbo_revenues!$A$2:$CS$5
Name _DLX482.USE: cbo_revenues_gdp!$A$2:$CS$5
Name _DLX482.USE: cbo_rgdp!$A$2:$CR$5
Name _DLX482.USE: omb_debt!$A$2:$DL$5
Name _DLX482.USE: omb_debt_gdp!$A$2:$DM$5
Name _DLX482.USE: omb_ngdp!$A$2:$DL$5
Name _DLX482.USE: cbo_debt_gdp!$A$2:$CS$5
Name _DLX55.USE: 'Fixed Assets'!$A$1:$G$4
Name _DLX6.USE: treasuries_zc!$A$2:$G$6
Name _DLX66.USE: 'Capital Share'!$A$1:$E$4
Name _DLX6644.USE: frbus_infl!$A$2:$G$6
Name _DLX7.USE: divyield!$A$2:$H$6
Name _DLX8.USE: dkw!$A$2:$H$6
Name _DLX9.USE: treas_holdings!$A$2:$I$6

Sheet final
A1: date | B1: obs | C1: i5y5y_zc | D1: i10y5y_zc | E1: i5y10y_zc | F1: i10y_zc | G1: i5y3m_zc | H1: i10y3m_zc | I1: debt_y0 | J1: debt_y5 | K1: debt_y10 | L1: deficit_y0 | M1: deficit_y5 | N1: deficit_y10 | O1: pr_deficit_y0 | P1: pr_deficit_y5 | Q1: pr_deficit_y10 | R1: revenues_y0 | S1: revenues_y5 | T1: revenues_y10 | U1: outlays_y0 | V1: outlays_y5 | W1: outlays_y10 | X1: interest_y0 | Y1: interest_y5 | Z1: interest_y10 | AA1: rgdp_y0 | AB1: rgdp_y5 | AC1: rgdp_y10 | AD1: frbus_pi_y10 | AE1: spf_cpi_y5y5 | AF1: spf_cpi_y10 | AG1: fed_gdp | AH1: foreign_gdp | AI1: divyld | AJ1: ffr | AK1: dkw_ifit_y5y5 | AL1: dkw_rshort_y5y5 | AM1: dkw_rtp_y5y5 | AN1: dkw_epi_y5y5 | AO1: dkw_pirp_y5y5 | AP1: acm_ifit_y10 | AQ1: acm_tp_y10 | AR1: acm_rn_y10 | AS1: cr_ishort_y5y5 | AT1: cr_tp_y10 | AU1: cr_ishort_y10
A2: 27760 | B2: 1 | C2: =VLOOKUP(A2,treasuries_zc!$B$7:$J$1000,_xlfn.XMATCH(C$1,treasuries_zc!$B$1:$J$1,1),FALSE) -> 8.0093745 | D2: =VLOOKUP(A2,treasuries_zc!$B$7:$J$1000,_xlfn.XMATCH(D$1,treasuries_zc!$B$1:$J$1,1),FALSE) -> 8.0089578 | E2: =VLOOKUP(A2,treasuries_zc!$B$7:$J$1000,_xlfn.XMATCH(E$1,treasuries_zc!$B$1:$J$1,1),FALSE) -> 8.0091662 | F2: =VLOOKUP(A2,treasuries_zc!$B$7:$J$1000,_xlfn.XMATCH(F$1,treasuries_zc!$B$1:$J$1,1),FALSE) -> 7.6687 | G2: =VLOOKUP(A2,treasuries_zc!$B$7:$J$1000,_xlfn.XMATCH(G$1,treasuries_zc!$B$1:$J$1,1),FALSE) -> 8.0073 | H2: =VLOOKUP(A2,treasuries_zc!$B$7:$J$1000,_xlfn.XMATCH(H$1,treasuries_zc!$B$1:$J$1,1),FALSE) -> 8.0085 | I2: =cbo_debt_gdp!CX7 -> 27.669617 | J2: =cbo_debt_gdp!CZ7 -> 10.731707 | K2: =cbo_debt_gdp!DB7 -> #N/A | L2: =cbo_deficit_gdp!CX7 -> 4.3657817 | M2: =cbo_deficit_gdp!CZ7 -> -2.9918699 | N2: =cbo_deficit_gdp!DB7 -> #N/A | O2: =cbo_primary_deficit_gdp!CX7 -> 2.7728614 | P2: =cbo_primary_deficit_gdp!CZ7 -> -4.2276423 | Q2: =cbo_primary_deficit_gdp!DB7 -> #N/A | R2: =cbo_revenues_gdp!CX7 -> 17.758112 | S2: =cbo_revenues_gdp!CZ7 -> 21.203252 | T2: =cbo_revenues_gdp!DB7 -> #N/A | U2: =cbo_outlays_gdp!CX7 -> 22.123894 | V2: =cbo_outlays_gdp!CZ7 -> 18.211382 | W2: =cbo_outlays_gdp!DB7 -> #N/A | X2: =cbo_interest_gdp!CX7 -> 1.5929204 | Y2: =cbo_interest_gdp!CZ7 -> 1.2357724 | Z2: =cbo_interest_gdp!DB7 -> #N/A | AA2: =cbo_rgdp!CX7 -> 6.7 | AB2: =cbo_rgdp!CZ7 -> 6.6 | AC2: =cbo_rgdp!DB7 -> #N/A | AD2: =IFERROR(IFERROR(VLOOKUP(A2,frbus_infl!$B$7:$H$1000,7,FALSE),VLOOKUP(A2,frbus_infl!$C$7:$H$1000,6,FALSE)),VLOOKUP(A2,frbus_infl!$D$7:$H$1000,5,FALSE)) -> 4.8788333 | AE2: =IFERROR(IFERROR(VLOOKUP(A2,frbus_infl!$B$7:$I$1000,8,FALSE),VLOOKUP(A2,frbus_infl!$C$7:$I$1000,7,FALSE)),VLOOKUP(A2,frbus_infl!$D$7:$I$1000,6,FALSE)) -> #N/A | AF2: =IFERROR(IFERROR(VLOOKUP(A2,frbus_infl!$B$7:$I$1000,5,FALSE),VLOOKUP(A2,frbus_infl!$C$7:$I$1000,4,FALSE)),VLOOKUP(A2,frbus_infl!$D$7:$I$1000,3,FALSE)) -> #N/A | AG2: =IFERROR(IFERROR(VLOOKUP(A2,treas_holdings!$B$7:$I$1000,7,FALSE),VLOOKUP(A2,treas_holdings!$C$7:$I$1000,6,FALSE)),VLOOKUP(A2,treas_holdings!$D$7:$I$1000,5,FALSE)) -> 4.7950014 | AH2: =IFERROR(IFERROR(VLOOKUP(A2,treas_holdings!$B$7:$I$1000,8,FALSE),VLOOKUP(A2,treas_holdings!$C$7:$I$1000,7,FALSE)),VLOOKUP(A2,treas_holdings!$D$7:$I$1000,6,FALSE)) -> 3.4687723 | AI2: =IFERROR(IFERROR(VLOOKUP(A2,divyield!$B$7:$E$1001,4,FALSE),VLOOKUP(A2,divyield!$C$7:$E$1001,3,FALSE)),VLOOKUP(A2,divyield!$D$7:$E$1001,2,FALSE)) -> 3.4960883 | AJ2: =VLOOKUP(A2,ffr!$B$6:$C$1000,2) -> 4.84 | AK2: =VLOOKUP(A2,dkw!$B$7:$H$1001,3,FALSE) -> #N/A | AL2: =VLOOKUP(A2,dkw!$B$7:$H$1001,4,FALSE) -> #N/A | AM2: =VLOOKUP(A2,dkw!$B$7:$H$1001,5,FALSE) -> #N/A | AN2: =VLOOKUP(A2,dkw!$B$7:$H$1001,6,FALSE) -> #N/A | AO2: =VLOOKUP(A2,dkw!$B$7:$H$1001,7,FALSE) -> #N/A | AP2: =VLOOKUP(A2,acm!B$7:E$1001,2,FALSE) -> 7.66327 | AQ2: =VLOOKUP(A2,acm!B$7:E$1001,3,FALSE) -> 2.41473 | AR2: =VLOOKUP(A2,acm!B$7:E$1001,4,FALSE) -> 5.24854 | AS2: =VLOOKUP(A2,cr!B$7:F$1001,5,FALSE) -> #N/A | AT2: =VLOOKUP(A2,cr!B$7:F$1001,4,FALSE) -> #N/A | AU2: =VLOOKUP(A2,cr!B$7:F$1001,2,FALSE) -> #N/A
A3: 28095 | B3: 2 | C3: =VLOOKUP(A3,treasuries_zc!$B$7:$J$1000,_xlfn.XMATCH(C$1,treasuries_zc!$B$1:$J$1,1),FALSE) -> 7.2808838 | D3: =VLOOKUP(A3,treasuries_zc!$B$7:$J$1000,_xlfn.XMATCH(D$1,treasuries_zc!$B$1:$J$1,1),FALSE) -> 7.350582 | E3: =VLOOKUP(A3,treasuries_zc!$B$7:$J$1000,_xlfn.XMATCH(E$1,treasuries_zc!$B$1:$J$1,1),FALSE) -> 7.3157272 | F3: =VLOOKUP(A3,treasuries_zc!$B$7:$J$1000,_xlfn.XMATCH(F$1,treasuries_zc!$B$1:$J$1,1),FALSE) -> 6.7344 | G3: =VLOOKUP(A3,treasuries_zc!$B$7:$J$1000,_xlfn.XMATCH(G$1,treasuries_zc!$B$1:$J$1,1),FALSE) -> 7.134 | H3: =VLOOKUP(A3,treasuries_zc!$B$7:$J$1000,_xlfn.XMATCH(H$1,treasuries_zc!$B$1:$J$1,1),FALSE) -> 7.3424 | I3: =cbo_debt_gdp!CX8 -> 28.75817 | J3: =cbo_debt_gdp!CZ8 -> 19.343066 | K3: =cbo_debt_gdp!DB8 -> #N/A | L3: =cbo_deficit_gdp!CX8 -> 2.7777778 | M3: =cbo_deficit_gdp!CZ8 -> -1.6788321 | N3: =cbo_deficit_gdp!DB8 -> #N/A | O3: =cbo_primary_deficit_gdp!CX8 -> 1.1437908 | P3: =cbo_primary_deficit_gdp!CZ8 -> -3.1386861 | Q3: =cbo_primary_deficit_gdp!DB8 -> #N/A | R3: =cbo_revenues_gdp!CX8 -> 19.771242 | S3: =cbo_revenues_gdp!CZ8 -> 21.678832 | T3: =cbo_revenues_gdp!DB8 -> #N/A | U3: =cbo_outlays_gdp!CX8 -> 22.494553 | V3: =cbo_outlays_gdp!CZ8 -> 20 | W3: =cbo_outlays_gdp!DB8 -> #N/A | X3: =cbo_interest_gdp!CX8 -> 1.6339869 | Y3: =cbo_interest_gdp!CZ8 -> 1.459854 | Z3: =cbo_interest_gdp!DB8 -> #N/A | AA3: =cbo_rgdp!CX8 -> 5.5 | AB3: =cbo_rgdp!CZ8 -> 4.8 | AC3: =cbo_rgdp!DB8 -> #N/A | AD3: =IFERROR(IFERROR(VLOOKUP(A3,frbus_infl!$B$7:$H$1000,7,FALSE),VLOOKUP(A3,frbus_infl!$C$7:$H$1000,6,FALSE)),VLOOKUP(A3,frbus_infl!$D$7:$H$1000,5,FALSE)) -> 4.4988 | AE3: =IFERROR(IFERROR(VLOOKUP(A3,frbus_infl!$B$7:$I$1000,8,FALSE),VLOOKUP(A3,frbus_infl!$C$7:$I$1000,7,FALSE)),VLOOKUP(A3,frbus_infl!$D$7:$I$1000,6,FALSE)) -> #N/A | AF3: =IFERROR(IFERROR(VLOOKUP(A3,frbus_infl!$B$7:$I$1000,5,FALSE),VLOOKUP(A3,frbus_infl!$C$7:$I$1000,4,FALSE)),VLOOKUP(A3,frbus_infl!$D$7:$I$1000,3,FALSE)) -> #N/A | AG3: =IFERROR(IFERROR(VLOOKUP(A3,treas_holdings!$B$7:$I$1000,7,FALSE),VLOOKUP(A3,treas_holdings!$C$7:$I$1000,6,FALSE)),VLOOKUP(A3,treas_holdings!$D$7:$I$1000,5,FALSE)) -> 4.821796 | AH3: =IFERROR(IFERROR(VLOOKUP(A3,treas_holdings!$B$7:$I$1000,8,FALSE),VLOOKUP(A3,treas_holdings!$C$7:$I$1000,7,FALSE)),VLOOKUP(A3,treas_holdings!$D$7:$I$1000,6,FALSE)) -> 3.6475728 | AI3: =IFERROR(IFERROR(VLOOKUP(A3,divyield!$B$7:$E$1001,4,FALSE),VLOOKUP(A3,divyield!$C$7:$E$1001,3,FALSE)),VLOOKUP(A3,divyield!$D$7:$E$1001,2,FALSE)) -> 4.0442406 | AJ3: =VLOOKUP(A3,ffr!$B$6:$C$1000,2) -> 4.17 | AK3: =VLOOKUP(A3,dkw!$B$7:$H$1001,3,FALSE) -> #N/A | AL3: =VLOOKUP(A3,dkw!$B$7:$H$1001,4,FALSE) -> #N/A | AM3: =VLOOKUP(A3,dkw!$B$7:$H$1001,5,FALSE) -> #N/A | AN3: =VLOOKUP(A3,dkw!$B$7:$H$1001,6,FALSE) -> #N/A | AO3: =VLOOKUP(A3,dkw!$B$7:$H$1001,7,FALSE) -> #N/A | AP3: =VLOOKUP(A3,acm!B$7:E$1001,2,FALSE) -> 6.74373 | AQ3: =VLOOKUP(A3,acm!B$7:E$1001,3,FALSE) -> 2.17446 | AR3: =VLOOKUP(A3,acm!B$7:E$1001,4,FALSE) -> 4.56927 | AS3: =VLOOKUP(A3,cr!B$7:F$1001,5,FALSE) -> #N/A | AT3: =VLOOKUP(A3,cr!B$7:F$1001,4,FALSE) -> #N/A | AU3: =VLOOKUP(A3,cr!B$7:F$1001,2,FALSE) -> #N/A
A4: 28460 | B4: 3 | C4: =VLOOKUP(A4,treasuries_zc!$B$7:$J$1000,_xlfn.XMATCH(C$1,treasuries_zc!$B$1:$J$1,1),FALSE) -> 7.9051504 | D4: =VLOOKUP(A4,treasuries_zc!$B$7:$J$1000,_xlfn.XMATCH(D$1,treasuries_zc!$B$1:$J$1,1),FALSE) -> 7.9350938 | E4: =VLOOKUP(A4,treasuries_zc!$B$7:$J$1000,_xlfn.XMATCH(E$1,treasuries_zc!$B$1:$J$1,1),FALSE) -> 7.9201211 | F4: =VLOOKUP(A4,treasuries_zc!$B$7:$J$1000,_xlfn.XMATCH(F$1,treasuries_zc!$B$1:$J$1,1),FALSE) -> 7.6847 | G4: =VLOOKUP(A4,treasuries_zc!$B$7:$J$1000,_xlfn.XMATCH(G$1,treasuries_zc!$B$1:$J$1,1),FALSE) -> 7.8494 | H4: =VLOOKUP(A4,treasuries_zc!$B$7:$J$1000,_xlfn.XMATCH(H$1,treasuries_zc!$B$1:$J$1,1),FALSE) -> 7.9313 | I4: =cbo_debt_gdp!CX9 -> 29.654837 | J4: =cbo_debt_gdp!CZ9 -> 18.544982 | K4: =cbo_debt_gdp!DB9 -> #N/A | L4: =cbo_deficit_gdp!CX9 -> 2.9654837 | M4: =cbo_deficit_gdp!CZ9 -> -2.0136408 | N4: =cbo_deficit_gdp!DB9 -> #N/A | O4: =cbo_primary_deficit_gdp!CX9 -> 1.3612056 | P4: =cbo_primary_deficit_gdp!CZ9 -> -3.37772 | Q4: =cbo_primary_deficit_gdp!DB9 -> #N/A | R4: =cbo_revenues_gdp!CX9 -> 19.299951 | S4: =cbo_revenues_gdp!CZ9 -> 21.695356 | T4: =cbo_revenues_gdp!DB9 -> #N/A | U4: =cbo_outlays_gdp!CX9 -> 22.265435 | V4: =cbo_outlays_gdp!CZ9 -> 19.681715 | W4: =cbo_outlays_gdp!DB9 -> #N/A | X4: =cbo_interest_gdp!CX9 -> 1.6042781 | Y4: =cbo_interest_gdp!CZ9 -> 1.3640792 | Z4: =cbo_interest_gdp!DB9 -> #N/A | AA4: =cbo_rgdp!CX9 -> 5.2 | AB4: =cbo_rgdp!CZ9 -> 4.8 | AC4: =cbo_rgdp!DB9 -> #N/A | AD4: =IFERROR(IFERROR(VLOOKUP(A4,frbus_infl!$B$7:$H$1000,7,FALSE),VLOOKUP(A4,frbus_infl!$C$7:$H$1000,6,FALSE)),VLOOKUP(A4,frbus_infl!$D$7:$H$1000,5,FALSE)) -> 4.8504 | AE4: =IFERROR(IFERROR(VLOOKUP(A4,frbus_infl!$B$7:$I$1000,8,FALSE),VLOOKUP(A4,frbus_infl!$C$7:$I$1000,7,FALSE)),VLOOKUP(A4,frbus_infl!$D$7:$I$1000,6,FALSE)) -> #N/A | AF4: =IFERROR(IFERROR(VLOOKUP(A4,frbus_infl!$B$7:$I$1000,5,FALSE),VLOOKUP(A4,frbus_infl!$C$7:$I$1000,4,FALSE)),VLOOKUP(A4,frbus_infl!$D$7:$I$1000,3,FALSE)) -> #N/A | AG4: =IFERROR(IFERROR(VLOOKUP(A4,treas_holdings!$B$7:$I$1000,7,FALSE),VLOOKUP(A4,treas_holdings!$C$7:$I$1000,6,FALSE)),VLOOKUP(A4,treas_holdings!$D$7:$I$1000,5,FALSE)) -> 4.6628471 | AH4: =IFERROR(IFERROR(VLOOKUP(A4,treas_holdings!$B$7:$I$1000,8,FALSE),VLOOKUP(A4,treas_holdings!$C$7:$I$1000,7,FALSE)),VLOOKUP(A4,treas_holdings!$D$7:$I$1000,6,FALSE)) -> 4.6708867 | AI4: =IFERROR(IFERROR(VLOOKUP(A4,divyield!$B$7:$E$1001,4,FALSE),VLOOKUP(A4,divyield!$C$7:$E$1001,3,FALSE)),VLOOKUP(A4,divyield!$D$7:$E$1001,2,FALSE)) -> 5.2676489 | AJ4: =VLOOKUP(A4,ffr!$B$6:$C$1000,2) -> 6.53 | AK4: =VLOOKUP(A4,dkw!$B$7:$H$1001,3,FALSE) -> #N/A | AL4: =VLOOKUP(A4,dkw!$B$7:$H$1001,4,FALSE) -> #N/A | AM4: =VLOOKUP(A4,dkw!$B$7:$H$1001,5,FALSE) -> #N/A | AN4: =VLOOKUP(A4,dkw!$B$7:$H$1001,6,FALSE) -> #N/A | AO4: =VLOOKUP(A4,dkw!$B$7:$H$1001,7,FALSE) -> #N/A | AP4: =VLOOKUP(A4,acm!B$7:E$1001,2,FALSE) -> 7.69327 | AQ4: =VLOOKUP(A4,acm!B$7:E$1001,3,FALSE) -> 2.01431 | AR4: =VLOOKUP(A4,acm!B$7:E$1001,4,FALSE) -> 5.67896 | AS4: =VLOOKUP(A4,cr!B$7:F$1001,5,FALSE) -> #N/A | AT4: =VLOOKUP(A4,cr!B$7:F$1001,4,FALSE) -> #N/A | AU4: =VLOOKUP(A4,cr!B$7:F$1001,2,FALSE) -> #N/A
A5: 28856 | B5: 4 | C5: =VLOOKUP(A5,treasuries_zc!$B$7:$J$1000,_xlfn.XMATCH(C$1,treasuries_zc!$B$1:$J$1,1),FALSE) -> 8.3691604 | D5: =VLOOKUP(A5,treasuries_zc!$B$7:$J$1000,_xlfn.XMATCH(D$1,treasuries_zc!$B$1:$J$1,1),FALSE) -> 8.3689203 | E5: =VLOOKUP(A5,treasuries_zc!$B$7:$J$1000,_xlfn.XMATCH(E$1,treasuries_zc!$B$1:$J$1,1),FALSE) -> 8.3690404 | F5: =VLOOKUP(A5,treasuries_zc!$B$7:$J$1000,_xlfn.XMATCH(F$1,treasuries_zc!$B$1:$J$1,1),FALSE) -> 8.5668 | G5: =VLOOKUP(A5,treasuries_zc!$B$7:$J$1000,_xlfn.XMATCH(G$1,treasuries_zc!$B$1:$J$1,1),FALSE) -> 8.3689 | H5: =VLOOKUP(A5,treasuries_zc!$B$7:$J$1000,_xlfn.XMATCH(H$1,treasuries_zc!$B$1:$J$1,1),FALSE) -> 8.3687 | I5: =cbo_debt_gdp!CX10 -> 28.173913 | J5: =cbo_debt_gdp!CZ10 -> 15.02444 | K5: =cbo_debt_gdp!DB10 -> #N/A | L5: =cbo_deficit_gdp!CX10 -> 1.7826087 | M5: =cbo_deficit_gdp!CZ10 -> -2.4183175 | N5: =cbo_deficit_gdp!DB10 -> #N/A | O5: =cbo_primary_deficit_gdp!CX10 -> 0.26086957 | P5: =cbo_primary_deficit_gdp!CZ10 -> -3.5194237 | Q5: =cbo_primary_deficit_gdp!DB10 -> #N/A | R5: =cbo_revenues_gdp!CX10 -> 19.695652 | S5: =cbo_revenues_gdp!CZ10 -> 21.842038 | T5: =cbo_revenues_gdp!DB10 -> #N/A | U5: =cbo_outlays_gdp!CX10 -> 21.478261 | V5: =cbo_outlays_gdp!CZ10 -> 19.42372 | W5: =cbo_outlays_gdp!DB10 -> #N/A | X5: =cbo_interest_gdp!CX10 -> 1.5217391 | Y5: =cbo_interest_gdp!CZ10 -> 1.1011063 | Z5: =cbo_interest_gdp!DB10 -> #N/A | AA5: =cbo_rgdp!CX10 -> 3.9 | AB5: =cbo_rgdp!CZ10 -> 4.5 | AC5: =cbo_rgdp!DB10 -> #N/A | AD5: =IFERROR(IFERROR(VLOOKUP(A5,frbus_infl!$B$7:$H$1000,7,FALSE),VLOOKUP(A5,frbus_infl!$C$7:$H$1000,6,FALSE)),VLOOKUP(A5,frbus_infl!$D$7:$H$1000,5,FALSE)) -> 6.1473 | AE5: =IFERROR(IFERROR(VLOOKUP(A5,frbus_infl!$B$7:$I$1000,8,FALSE),VLOOKUP(A5,frbus_infl!$C$7:$I$1000,7,FALSE)),VLOOKUP(A5,frbus_infl!$D$7:$I$1000,6,FALSE)) -> #N/A | AF5: =IFERROR(IFERROR(VLOOKUP(A5,frbus_infl!$B$7:$I$1000,5,FALSE),VLOOKUP(A5,frbus_infl!$C$7:$I$1000,4,FALSE)),VLOOKUP(A5,frbus_infl!$D$7:$I$1000,3,FALSE)) -> #N/A | AG5: =IFERROR(IFERROR(VLOOKUP(A5,treas_holdings!$B$7:$I$1000,7,FALSE),VLOOKUP(A5,treas_holdings!$C$7:$I$1000,6,FALSE)),VLOOKUP(A5,treas_holdings!$D$7:$I$1000,5,FALSE)) -> 4.3243885 | AH5: =IFERROR(IFERROR(VLOOKUP(A5,treas_holdings!$B$7:$I$1000,8,FALSE),VLOOKUP(A5,treas_holdings!$C$7:$I$1000,7,FALSE)),VLOOKUP(A5,treas_holdings!$D$7:$I$1000,6,FALSE)) -> 4.5578643 | AI5: =IFERROR(IFERROR(VLOOKUP(A5,divyield!$B$7:$E$1001,4,FALSE),VLOOKUP(A5,divyield!$C$7:$E$1001,3,FALSE)),VLOOKUP(A5,divyield!$D$7:$E$1001,2,FALSE)) -> 5.5197287 | AJ5: =VLOOKUP(A5,ffr!$B$6:$C$1000,2) -> 10.57 | AK5: =VLOOKUP(A5,dkw!$B$7:$H$1001,3,FALSE) -> #N/A | AL5: =VLOOKUP(A5,dkw!$B$7:$H$1001,4,FALSE) -> #N/A | AM5: =VLOOKUP(A5,dkw!$B$7:$H$1001,5,FALSE) -> #N/A | AN5: =VLOOKUP(A5,dkw!$B$7:$H$1001,6,FALSE) -> #N/A | AO5: =VLOOKUP(A5,dkw!$B$7:$H$1001,7,FALSE) -> #N/A | AP5: =VLOOKUP(A5,acm!B$7:E$1001,2,FALSE) -> 8.59173 | AQ5: =VLOOKUP(A5,acm!B$7:E$1001,3,FALSE) -> 1.53715 | AR5: =VLOOKUP(A5,acm!B$7:E$1001,4,FALSE) -> 7.05458 | AS5: =VLOOKUP(A5,cr!B$7:F$1001,5,FALSE) -> #N/A | AT5: =VLOOKUP(A5,cr!B$7:F$1001,4,FALSE) -> #N/A | AU5: =VLOOKUP(A5,cr!B$7:F$1001,2,FALSE) -> #N/A
A6: 29252 | B6: 5 | C6: =VLOOKUP(A6,treasuries_zc!$B$7:$J$1000,_xlfn.XMATCH(C$1,treasuries_zc!$B$1:$J$1,1),FALSE) -> 11.600305 | D6: =VLOOKUP(A6,treasuries_zc!$B$7:$J$1000,_xlfn.XMATCH(D$1,treasuries_zc!$B$1:$J$1,1),FALSE) -> 11.828698 | E6: =VLOOKUP(A6,treasuries_zc!$B$7:$J$1000,_xlfn.XMATCH(E$1,treasuries_zc!$B$1:$J$1,1),FALSE) -> 11.714443 | F6: =VLOOKUP(A6,treasuries_zc!$B$7:$J$1000,_xlfn.XMATCH(F$1,treasuries_zc!$B$1:$J$1,1),FALSE) -> 12.0101 | G6: =VLOOKUP(A6,treasuries_zc!$B$7:$J$1000,_xlfn.XMATCH(G$1,treasuries_zc!$B$1:$J$1,1),FALSE) -> 11.2688 | H6: =VLOOKUP(A6,treasuries_zc!$B$7:$J$1000,_xlfn.XMATCH(H$1,treasuries_zc!$B$1:$J$1,1),FALSE) -> 11.8002 | I6: =cbo_debt_gdp!CX11 -> 27.306977 | J6: =cbo_debt_gdp!CZ11 -> 15.871658 | K6: =cbo_debt_gdp!DB11 -> #N/A | L6: =cbo_deficit_gdp!CX11 -> 1.7565891 | M6: =cbo_deficit_gdp!CZ11 -> -1.3604278 | N6: =cbo_deficit_gdp!DB11 -> #N/A | O6: =cbo_primary_deficit_gdp!CX11 -> -0.27945736 | P6: =cbo_primary_deficit_gdp!CZ11 -> -2.6528342 | Q6: =cbo_primary_deficit_gdp!DB11 -> #N/A | R6: =cbo_revenues_gdp!CX11 -> 20.6 | S6: =cbo_revenues_gdp!CZ11 -> 21.2 | T6: =cbo_revenues_gdp!DB11 -> #N/A | U6: =cbo_outlays_gdp!CX11 -> 22.3 | V6: =cbo_outlays_gdp!CZ11 -> 19.9 | W6: =cbo_outlays_gdp!DB11 -> #N/A | X6: =cbo_interest_gdp!CX11 -> 2.0360465 | Y6: =cbo_interest_gdp!CZ11 -> 1.2924064 | Z6: =cbo_interest_gdp!DB11 -> #N/A | AA6: =cbo_rgdp!CX11 -> -0.9 | AB6: =cbo_rgdp!CZ11 -> 3.8 | AC6: =cbo_rgdp!DB11 -> #N/A | AD6: =IFERROR(IFERROR(VLOOKUP(A6,frbus_infl!$B$7:$H$1000,7,FALSE),VLOOKUP(A6,frbus_infl!$C$7:$H$1000,6,FALSE)),VLOOKUP(A6,frbus_infl!$D$7:$H$1000,5,FALSE)) -> 6.7167 | AE6: =IFERROR(IFERROR(VLOOKUP(A6,frbus_infl!$B$7:$I$1000,8,FALSE),VLOOKUP(A6,frbus_infl!$C$7:$I$1000,7,FALSE)),VLOOKUP(A6,frbus_infl!$D$7:$I$1000,6,FALSE)) -> #N/A | AF6: =IFERROR(IFERROR(VLOOKUP(A6,frbus_infl!$B$7:$I$1000,5,FALSE),VLOOKUP(A6,frbus_infl!$C$7:$I$1000,4,FALSE)),VLOOKUP(A6,frbus_infl!$D$7:$I$1000,3,FALSE)) -> #N/A | AG6: =IFERROR(IFERROR(VLOOKUP(A6,treas_holdings!$B$7:$I$1000,7,FALSE),VLOOKUP(A6,treas_holdings!$C$7:$I$1000,6,FALSE)),VLOOKUP(A6,treas_holdings!$D$7:$I$1000,5,FALSE)) -> 4.1484694 | AH6: =IFERROR(IFERROR(VLOOKUP(A6,treas_holdings!$B$7:$I$1000,8,FALSE),VLOOKUP(A6,treas_holdings!$C$7:$I$1000,7,FALSE)),VLOOKUP(A6,treas_holdings!$D$7:$I$1000,6,FALSE)) -> 3.4551222 | AI6: =IFERROR(IFERROR(VLOOKUP(A6,divyield!$B$7:$E$1001,4,FALSE),VLOOKUP(A6,divyield!$C$7:$E$1001,3,FALSE)),VLOOKUP(A6,divyield!$D$7:$E$1001,2,FALSE)) -> 5.3379155 | AJ6: =VLOOKUP(A6,ffr!$B$6:$C$1000,2) -> 16.33 | AK6: =VLOOKUP(A6,dkw!$B$7:$H$1001,3,FALSE) -> #N/A | AL6: =VLOOKUP(A6,dkw!$B$7:$H$1001,4,FALSE) -> #N/A | AM6: =VLOOKUP(A6,dkw!$B$7:$H$1001,5,FALSE) -> #N/A | AN6: =VLOOKUP(A6,dkw!$B$7:$H$1001,6,FALSE) -> #N/A | AO6: =VLOOKUP(A6,dkw!$B$7:$H$1001,7,FALSE) -> #N/A | AP6: =VLOOKUP(A6,acm!B$7:E$1001,2,FALSE) -> 12.05624 | AQ6: =VLOOKUP(A6,acm!B$7:E$1001,3,FALSE) -> 2.80265 | AR6: =VLOOKUP(A6,acm!B$7:E$1001,4,FALSE) -> 9.25359 | AS6: =VLOOKUP(A6,cr!B$7:F$1001,5,FALSE) -> #N/A | AT6: =VLOOKUP(A6,cr!B$7:F$1001,4,FALSE) -> #N/A | AU6: =VLOOKUP(A6,cr!B$7:F$1001,2,FALSE) -> #N/A
A7: 29768 | B7: 6 | C7: =VLOOKUP(A7,treasuries_zc!$B$7:$J$1000,_xlfn.XMATCH(C$1,treasuries_zc!$B$1:$J$1,1),FALSE) -> 13.067212 | D7: =VLOOKUP(A7,treasuries_zc!$B$7:$J$1000,_xlfn.XMATCH(D$1,treasuries_zc!$B$1:$J$1,1),FALSE) -> 12.978691 | E7: =VLOOKUP(A7,treasuries_zc!$B$7:$J$1000,_xlfn.XMATCH(E$1,treasuries_zc!$B$1:$J$1,1),FALSE) -> 13.022943 | F7: =VLOOKUP(A7,treasuries_zc!$B$7:$J$1000,_xlfn.XMATCH(F$1,treasuries_zc!$B$1:$J$1,1),FALSE) -> 13.641 | G7: =VLOOKUP(A7,treasuries_zc!$B$7:$J$1000,_xlfn.XMATCH(G$1,treasuries_zc!$B$1:$J$1,1),FALSE) -> 13.2584 | H7: =VLOOKUP(A7,treasuries_zc!$B$7:$J$1000,_xlfn.XMATCH(H$1,treasuries_zc!$B$1:$J$1,1),FALSE) -> 12.9831 | I7: =cbo_debt_gdp!CX12 -> 26.916667 | J7: =cbo_debt_gdp!CZ12 -> 7.1803828 | K7: =cbo_debt_gdp!DB12 -> #N/A | L7: =cbo_deficit_gdp!CX12 -> 1.7 | M7: =cbo_deficit_gdp!CZ12 -> -4.3 | N7: =cbo_deficit_gdp!DB12 -> #N/A | O7: =cbo_primary_deficit_gdp!CX12 -> -0.6375 | P7: =cbo_primary_deficit_gdp!CZ12 -> -5.5138756 | Q7: =cbo_primary_deficit_gdp!DB12 -> #N/A | R7: =cbo_revenues_gdp!CX12 -> 21.4 | S7: =cbo_revenues_gdp!CZ12 -> 23.9 | T7: =cbo_revenues_gdp!DB12 -> #N/A | U7: =cbo_outlays_gdp!CX12 -> 23.1 | V7: =cbo_outlays_gdp!CZ12 -> 19.6 | W7: =cbo_outlays_gdp!DB12 -> #N/A | X7: =cbo_interest_gdp!CX12 -> 2.3 | Y7: =cbo_interest_gdp!CZ12 -> 1.2 | Z7: =cbo_interest_gdp!DB12 -> #N/A | AA7: =cbo_rgdp!CX12 -> 2 | AB7: =cbo_rgdp!CZ12 -> 4.2 | AC7: =cbo_rgdp!DB12 -> #N/A | AD7: =IFERROR(IFERROR(VLOOKUP(A7,frbus_infl!$B$7:$H$1000,7,FALSE),VLOOKUP(A7,frbus_infl!$C$7:$H$1000,6,FALSE)),VLOOKUP(A7,frbus_infl!$D$7:$H$1000,5,FALSE)) -> 7.22 | AE7: =IFERROR(IFERROR(VLOOKUP(A7,frbus_infl!$B$7:$I$1000,8,FALSE),VLOOKUP(A7,frbus_infl!$C$7:$I$1000,7,FALSE)),VLOOKUP(A7,frbus_infl!$D$7:$I$1000,6,FALSE)) -> #N/A | AF7: =IFERROR(IFERROR(VLOOKUP(A7,frbus_infl!$B$7:$I$1000,5,FALSE),VLOOKUP(A7,frbus_infl!$C$7:$I$1000,4,FALSE)),VLOOKUP(A7,frbus_infl!$D$7:$I$1000,3,FALSE)) -> #N/A | AG7: =IFERROR(IFERROR(VLOOKUP(A7,treas_holdings!$B$7:$I$1000,7,FALSE),VLOOKUP(A7,treas_holdings!$C$7:$I$1000,6,FALSE)),VLOOKUP(A7,treas_holdings!$D$7:$I$1000,5,FALSE)) -> 3.8131019 | AH7: =IFERROR(IFERROR(VLOOKUP(A7,treas_holdings!$B$7:$I$1000,8,FALSE),VLOOKUP(A7,treas_holdings!$C$7:$I$1000,7,FALSE)),VLOOKUP(A7,treas_holdings!$D$7:$I$1000,6,FALSE)) -> 3.4314237 | AI7: =IFERROR(IFERROR(VLOOKUP(A7,divyield!$B$7:$E$1001,4,FALSE),VLOOKUP(A7,divyield!$C$7:$E$1001,3,FALSE)),VLOOKUP(A7,divyield!$D$7:$E$1001,2,FALSE)) -> 6.3722535 | AJ7: =VLOOKUP(A7,ffr!$B$6:$C$1000,2) -> 17.46 | AK7: =VLOOKUP(A7,dkw!$B$7:$H$1001,3,FALSE) -> #N/A | AL7: =VLOOKUP(A7,dkw!$B$7:$H$1001,4,FALSE) -> #N/A | AM7: =VLOOKUP(A7,dkw!$B$7:$H$1001,5,FALSE) -> #N/A | AN7: =VLOOKUP(A7,dkw!$B$7:$H$1001,6,FALSE) -> #N/A | AO7: =VLOOKUP(A7,dkw!$B$7:$H$1001,7,FALSE) -> #N/A | AP7: =VLOOKUP(A7,acm!B$7:E$1001,2,FALSE) -> 13.64153 | AQ7: =VLOOKUP(A7,acm!B$7:E$1001,3,FALSE) -> 3.1892 | AR7: =VLOOKUP(A7,acm!B$7:E$1001,4,FALSE) -> 10.45233 | AS7: =VLOOKUP(A7,cr!B$7:F$1001,5,FALSE) -> #N/A | AT7: =VLOOKUP(A7,cr!B$7:F$1001,4,FALSE) -> #N/A | AU7: =VLOOKUP(A7,cr!B$7:F$1001,2,FALSE) -> #N/A
A8: 29983 | B8: 7 | C8: =VLOOKUP(A8,treasuries_zc!$B$7:$J$1000,_xlfn.XMATCH(C$1,treasuries_zc!$B$1:$J$1,1),FALSE) -> 13.398502 | D8: =VLOOKUP(A8,treasuries_zc!$B$7:$J$1000,_xlfn.XMATCH(D$1,treasuries_zc!$B$1:$J$1,1),FALSE) -> 14.173082 | E8: =VLOOKUP(A8,treasuries_zc!$B$7:$J$1000,_xlfn.XMATCH(E$1,treasuries_zc!$B$1:$J$1,1),FALSE) -> 13.785133 | F8: =VLOOKUP(A8,treasuries_zc!$B$7:$J$1000,_xlfn.XMATCH(F$1,treasuries_zc!$B$1:$J$1,1),FALSE) -> 13.4151 | G8: =VLOOKUP(A8,treasuries_zc!$B$7:$J$1000,_xlfn.XMATCH(G$1,treasuries_zc!$B$1:$J$1,1),FALSE) -> 13.0418 | H8: =VLOOKUP(A8,treasuries_zc!$B$7:$J$1000,_xlfn.XMATCH(H$1,treasuries_zc!$B$1:$J$1,1),FALSE) -> 13.8784 | I8: =cbo_debt_gdp!CX13 -> 29.888372 | J8: =cbo_debt_gdp!CZ13 -> 41 | K8: =cbo_debt_gdp!DB13 -> #N/A | L8: =cbo_deficit_gdp!CX13 -> 4.2 | M8: =cbo_deficit_gdp!CZ13 -> 5.4 | N8: =cbo_deficit_gdp!DB13 -> #N/A | O8: =cbo_primary_deficit_gdp!CX13 -> 1.4325581 | P8: =cbo_primary_deficit_gdp!CZ13 -> 2.04 | Q8: =cbo_primary_deficit_gdp!DB13 -> #N/A | R8: =cbo_revenues_gdp!CX13 -> 20.6 | S8: =cbo_revenues_gdp!CZ13 -> 17.7 | T8: =cbo_revenues_gdp!DB13 -> #N/A | U8: =cbo_outlays_gdp!CX13 -> 24.9 | V8: =cbo_outlays_gdp!CZ13 -> 23.1 | W8: =cbo_outlays_gdp!DB13 -> #N/A | X8: =cbo_interest_gdp!CX13 -> 2.8 | Y8: =cbo_interest_gdp!CZ13 -> 3.4 | Z8: =cbo_interest_gdp!DB13 -> #N/A | AA8: =cbo_rgdp!CX13 -> -0.1 | AB8: =cbo_rgdp!CZ13 -> 3.5 | AC8: =cbo_rgdp!DB13 -> #N/A | AD8: =IFERROR(IFERROR(VLOOKUP(A8,frbus_infl!$B$7:$H$1000,7,FALSE),VLOOKUP(A8,frbus_infl!$C$7:$H$1000,6,FALSE)),VLOOKUP(A8,frbus_infl!$D$7:$H$1000,5,FALSE)) -> 6.76 | AE8: =IFERROR(IFERROR(VLOOKUP(A8,frbus_infl!$B$7:$I$1000,8,FALSE),VLOOKUP(A8,frbus_infl!$C$7:$I$1000,7,FALSE)),VLOOKUP(A8,frbus_infl!$D$7:$I$1000,6,FALSE)) -> #N/A | AF8: =IFERROR(IFERROR(VLOOKUP(A8,frbus_infl!$B$7:$I$1000,5,FALSE),VLOOKUP(A8,frbus_infl!$C$7:$I$1000,4,FALSE)),VLOOKUP(A8,frbus_infl!$D$7:$I$1000,3,FALSE)) -> #N/A | AG8: =IFERROR(IFERROR(VLOOKUP(A8,treas_holdings!$B$7:$I$1000,7,FALSE),VLOOKUP(A8,treas_holdings!$C$7:$I$1000,6,FALSE)),VLOOKUP(A8,treas_holdings!$D$7:$I$1000,5,FALSE)) -> 3.7868247 | AH8: =IFERROR(IFERROR(VLOOKUP(A8,treas_holdings!$B$7:$I$1000,8,FALSE),VLOOKUP(A8,treas_holdings!$C$7:$I$1000,7,FALSE)),VLOOKUP(A8,treas_holdings!$D$7:$I$1000,6,FALSE)) -> 3.5328773 | AI8: =IFERROR(IFERROR(VLOOKUP(A8,divyield!$B$7:$E$1001,4,FALSE),VLOOKUP(A8,divyield!$C$7:$E$1001,3,FALSE)),VLOOKUP(A8,divyield!$D$7:$E$1001,2,FALSE)) -> 7.3683108 | AJ8: =VLOOKUP(A8,ffr!$B$6:$C$1000,2) -> 13.74 | AK8: =VLOOKUP(A8,dkw!$B$7:$H$1001,3,FALSE) -> #N/A | AL8: =VLOOKUP(A8,dkw!$B$7:$H$1001,4,FALSE) -> #N/A | AM8: =VLOOKUP(A8,dkw!$B$7:$H$1001,5,FALSE) -> #N/A | AN8: =VLOOKUP(A8,dkw!$B$7:$H$1001,6,FALSE) -> #N/A | AO8: =VLOOKUP(A8,dkw!$B$7:$H$1001,7,FALSE) -> #N/A | AP8: =VLOOKUP(A8,acm!B$7:E$1001,2,FALSE) -> 13.39092 | AQ8: =VLOOKUP(A8,acm!B$7:E$1001,3,FALSE) -> 4.19835 | AR8: =VLOOKUP(A8,acm!B$7:E$1001,4,FALSE) -> 9.19258 | AS8: =VLOOKUP(A8,cr!B$7:F$1001,5,FALSE) -> #N/A | AT8: =VLOOKUP(A8,cr!B$7:F$1001,4,FALSE) -> #N/A | AU8: =VLOOKUP(A8,cr!B$7:F$1001,2,FALSE) -> #N/A
A9: 30348 | B9: 8 | C9: =VLOOKUP(A9,treasuries_zc!$B$7:$J$1000,_xlfn.XMATCH(C$1,treasuries_zc!$B$1:$J$1,1),FALSE) -> 10.668087 | D9: =VLOOKUP(A9,treasuries_zc!$B$7:$J$1000,_xlfn.XMATCH(D$1,treasuries_zc!$B$1:$J$1,1),FALSE) -> 11.3867 | E9: =VLOOKUP(A9,treasuries_zc!$B$7:$J$1000,_xlfn.XMATCH(E$1,treasuries_zc!$B$1:$J$1,1),FALSE) -> 11.026812 | F9: =VLOOKUP(A9,treasuries_zc!$B$7:$J$1000,_xlfn.XMATCH(F$1,treasuries_zc!$B$1:$J$1,1),FALSE) -> 10.3548 | G9: =VLOOKUP(A9,treasuries_zc!$B$7:$J$1000,_xlfn.XMATCH(G$1,treasuries_zc!$B$1:$J$1,1),FALSE) -> 10.7422 | H9: =VLOOKUP(A9,treasuries_zc!$B$7:$J$1000,_xlfn.XMATCH(H$1,treasuries_zc!$B$1:$J$1,1),FALSE) -> 10.7676 | I9: =cbo_debt_gdp!CX14 -> 35.6 | J9: =cbo_debt_gdp!CZ14 -> 49.5 | K9: =cbo_debt_gdp!DB14 -> #N/A | L9: =cbo_deficit_gdp!CX14 -> 6.6 | M9: =cbo_deficit_gdp!CZ14 -> 5.9 | N9: =cbo_deficit_gdp!DB14 -> #N/A | O9: =cbo_primary_deficit_gdp!CX14 -> 3.8657143 | P9: =cbo_primary_deficit_gdp!CZ14 -> 3.1161972 | Q9: =cbo_primary_deficit_gdp!DB14 -> #N/A | R9: =cbo_revenues_gdp!CX14 -> 19 | S9: =cbo_revenues_gdp!CZ14 -> 18.3 | T9: =cbo_revenues_gdp!DB14 -> #N/A | U9: =cbo_outlays_gdp!CX14 -> 25 | V9: =cbo_outlays_gdp!CZ14 -> 23.9 | W9: =cbo_outlays_gdp!DB14 -> #N/A | X9: =cbo_interest_gdp!CX14 -> 2.7 | Y9: =cbo_interest_gdp!CZ14 -> 2.8 | Z9: =cbo_interest_gdp!DB14 -> #N/A | AA9: =cbo_rgdp!CX14 -> 2.1 | AB9: =cbo_rgdp!CZ14 -> 3.5 | AC9: =cbo_rgdp!DB14 -> #N/A | AD9: =IFERROR(IFERROR(VLOOKUP(A9,frbus_infl!$B$7:$H$1000,7,FALSE),VLOOKUP(A9,frbus_infl!$C$7:$H$1000,6,FALSE)),VLOOKUP(A9,frbus_infl!$D$7:$H$1000,5,FALSE)) -> 5.92 | AE9: =IFERROR(IFERROR(VLOOKUP(A9,frbus_infl!$B$7:$I$1000,8,FALSE),VLOOKUP(A9,frbus_infl!$C$7:$I$1000,7,FALSE)),VLOOKUP(A9,frbus_infl!$D$7:$I$1000,6,FALSE)) -> #N/A | AF9: =IFERROR(IFERROR(VLOOKUP(A9,frbus_infl!$B$7:$I$1000,5,FALSE),VLOOKUP(A9,frbus_infl!$C$7:$I$1000,4,FALSE)),VLOOKUP(A9,frbus_infl!$D$7:$I$1000,3,FALSE)) -> 5.3 | AG9: =IFERROR(IFERROR(VLOOKUP(A9,treas_holdings!$B$7:$I$1000,7,FALSE),VLOOKUP(A9,treas_holdings!$C$7:$I$1000,6,FALSE)),VLOOKUP(A9,treas_holdings!$D$7:$I$1000,5,FALSE)) -> 3.9342143 | AH9: =IFERROR(IFERROR(VLOOKUP(A9,treas_holdings!$B$7:$I$1000,8,FALSE),VLOOKUP(A9,treas_holdings!$C$7:$I$1000,7,FALSE)),VLOOKUP(A9,treas_holdings!$D$7:$I$1000,6,FALSE)) -> 3.6834514 | AI9: =IFERROR(IFERROR(VLOOKUP(A9,divyield!$B$7:$E$1001,4,FALSE),VLOOKUP(A9,divyield!$C$7:$E$1001,3,FALSE)),VLOOKUP(A9,divyield!$D$7:$E$1001,2,FALSE)) -> 5.7540656 | AJ9: =VLOOKUP(A9,ffr!$B$6:$C$1000,2) -> 8.53 | AK9: =VLOOKUP(A9,dkw!$B$7:$H$1001,3,FALSE) -> 10.7417 | AL9: =VLOOKUP(A9,dkw!$B$7:$H$1001,4,FALSE) -> 3.2954 | AM9: =VLOOKUP(A9,dkw!$B$7:$H$1001,5,FALSE) -> 2.9208 | AN9: =VLOOKUP(A9,dkw!$B$7:$H$1001,6,FALSE) -> 3.7725 | AO9: =VLOOKUP(A9,dkw!$B$7:$H$1001,7,FALSE) -> 0.753 | AP9: =VLOOKUP(A9,acm!B$7:E$1001,2,FALSE) -> 10.35693 | AQ9: =VLOOKUP(A9,acm!B$7:E$1001,3,FALSE) -> 3.55614 | AR9: =VLOOKUP(A9,acm!B$7:E$1001,4,FALSE) -> 6.80079 | AS9: =VLOOKUP(A9,cr!B$7:F$1001,5,FALSE) -> #N/A | AT9: =VLOOKUP(A9,cr!B$7:F$1001,4,FALSE) -> #N/A | AU9: =VLOOKUP(A9,cr!B$7:F$1001,2,FALSE) -> #N/A
A10: 30713 | B10: 9 | C10: =VLOOKUP(A10,treasuries_zc!$B$7:$J$1000,_xlfn.XMATCH(C$1,treasuries_zc!$B$1:$J$1,1),FALSE) -> 12.137928 | D10: =VLOOKUP(A10,treasuries_zc!$B$7:$J$1000,_xlfn.XMATCH(D$1,treasuries_zc!$B$1:$J$1,1),FALSE) -> 12.00709 | E10: =VLOOKUP(A10,treasuries_zc!$B$7:$J$1000,_xlfn.XMATCH(E$1,treasuries_zc!$B$1:$J$1,1),FALSE) -> 12.07249 | F10: =VLOOKUP(A10,treasuries_zc!$B$7:$J$1000,_xlfn.XMATCH(F$1,treasuries_zc!$B$1:$J$1,1),FALSE) -> 11.8333 | G10: =VLOOKUP(A10,treasuries_zc!$B$7:$J$1000,_xlfn.XMATCH(G$1,treasuries_zc!$B$1:$J$1,1),FALSE) -> 12.2385 | H10: =VLOOKUP(A10,treasuries_zc!$B$7:$J$1000,_xlfn.XMATCH(H$1,treasuries_zc!$B$1:$J$1,1),FALSE) -> 12.0395 | I10: =cbo_debt_gdp!CX15 -> 37.243896 | J10: =cbo_debt_gdp!CZ15 -> 49.377208 | K10: =cbo_debt_gdp!DB15 -> #N/A | L10: =cbo_deficit_gdp!CX15 -> 5.697446 | M10: =cbo_deficit_gdp!CZ15 -> 6.3022867 | N10: =cbo_deficit_gdp!DB15 -> #N/A | O10: =cbo_primary_deficit_gdp!CX15 -> 2.6662925 | P10: =cbo_primary_deficit_gdp!CZ15 -> 2.2308979 | Q10: =cbo_primary_deficit_gdp!DB15 -> #N/A | R10: =cbo_revenues_gdp!CX15 -> 18.607915 | S10: =cbo_revenues_gdp!CZ15 -> 18.888269 | T10: =cbo_revenues_gdp!DB15 -> #N/A | U10: =cbo_outlays_gdp!CX15 -> 24.305361 | V10: =cbo_outlays_gdp!CZ15 -> 25.190556 | W10: =cbo_outlays_gdp!DB15 -> #N/A | X10: =cbo_interest_gdp!CX15 -> 3.0311535 | Y10: =cbo_interest_gdp!CZ15 -> 4.0713887 | Z10: =cbo_interest_gdp!DB15 -> #N/A | AA10: =cbo_rgdp!CX15 -> 5.4 | AB10: =cbo_rgdp!CZ15 -> 3.3 | AC10: =cbo_rgdp!DB15 -> #N/A | AD10: =IFERROR(IFERROR(VLOOKUP(A10,frbus_infl!$B$7:$H$1000,7,FALSE),VLOOKUP(A10,frbus_infl!$C$7:$H$1000,6,FALSE)),VLOOKUP(A10,frbus_infl!$D$7:$H$1000,5,FALSE)) -> 6.18 | AE10: =IFERROR(IFERROR(VLOOKUP(A10,frbus_infl!$B$7:$I$1000,8,FALSE),VLOOKUP(A10,frbus_infl!$C$7:$I$1000,7,FALSE)),VLOOKUP(A10,frbus_infl!$D$7:$I$1000,6,FALSE)) -> #N/A | AF10: =IFERROR(IFERROR(VLOOKUP(A10,frbus_infl!$B$7:$I$1000,5,FALSE),VLOOKUP(A10,frbus_infl!$C$7:$I$1000,4,FALSE)),VLOOKUP(A10,frbus_infl!$D$7:$I$1000,3,FALSE)) -> 5.6 | AG10: =IFERROR(IFERROR(VLOOKUP(A10,treas_holdings!$B$7:$I$1000,7,FALSE),VLOOKUP(A10,treas_holdings!$C$7:$I$1000,6,FALSE)),VLOOKUP(A10,treas_holdings!$D$7:$I$1000,5,FALSE)) -> 3.8590108 | AH10: =IFERROR(IFERROR(VLOOKUP(A10,treas_holdings!$B$7:$I$1000,8,FALSE),VLOOKUP(A10,treas_holdings!$C$7:$I$1000,7,FALSE)),VLOOKUP(A10,treas_holdings!$D$7:$I$1000,6,FALSE)) -> 3.3121466 | AI10: =IFERROR(IFERROR(VLOOKUP(A10,divyield!$B$7:$E$1001,4,FALSE),VLOOKUP(A10,divyield!$C$7:$E$1001,3,FALSE)),VLOOKUP(A10,divyield!$D$7:$E$1001,2,FALSE)) -> 6.1924995 | AJ10: =VLOOKUP(A10,ffr!$B$6:$C$1000,2) -> 9.45 | AK10: =VLOOKUP(A10,dkw!$B$7:$H$1001,3,FALSE) -> 12.1545 | AL10: =VLOOKUP(A10,dkw!$B$7:$H$1001,4,FALSE) -> 3.823 | AM10: =VLOOKUP(A10,dkw!$B$7:$H$1001,5,FALSE) -> 3.4012 | AN10: =VLOOKUP(A10,dkw!$B$7:$H$1001,6,FALSE) -> 4.0289 | AO10: =VLOOKUP(A10,dkw!$B$7:$H$1001,7,FALSE) -> 0.9014 | AP10: =VLOOKUP(A10,acm!B$7:E$1001,2,FALSE) -> 11.84852 | AQ10: =VLOOKUP(A10,acm!B$7:E$1001,3,FALSE) -> 4.26572 | AR10: =VLOOKUP(A10,acm!B$7:E$1001,4,FALSE) -> 7.58279 | AS10: =VLOOKUP(A10,cr!B$7:F$1001,5,FALSE) -> #N/A | AT10: =VLOOKUP(A10,cr!B$7:F$1001,4,FALSE) -> #N/A | AU10: =VLOOKUP(A10,cr!B$7:F$1001,2,FALSE) -> #N/A
A11: 31079 | B11: 10 | C11: =VLOOKUP(A11,treasuries_zc!$B$7:$J$1000,_xlfn.XMATCH(C$1,treasuries_zc!$B$1:$J$1,1),FALSE) -> 12.151557 | D11: =VLOOKUP(A11,treasuries_zc!$B$7:$J$1000,_xlfn.XMATCH(D$1,treasuries_zc!$B$1:$J$1,1),FALSE) -> 12.343607 | E11: =VLOOKUP(A11,treasuries_zc!$B$7:$J$1000,_xlfn.XMATCH(E$1,treasuries_zc!$B$1:$J$1,1),FALSE) -> 12.247541 | F11: =VLOOKUP(A11,treasuries_zc!$B$7:$J$1000,_xlfn.XMATCH(F$1,treasuries_zc!$B$1:$J$1,1),FALSE) -> 11.7913 | G11: =VLOOKUP(A11,treasuries_zc!$B$7:$J$1000,_xlfn.XMATCH(G$1,treasuries_zc!$B$1:$J$1,1),FALSE) -> 12.2626 | H11: =VLOOKUP(A11,treasuries_zc!$B$7:$J$1000,_xlfn.XMATCH(H$1,treasuries_zc!$B$1:$J$1,1),FALSE) -> 12.1218 | I11: =cbo_debt_gdp!CX16 -> 39.584955 | J11: =cbo_debt_gdp!CZ16 -> 49.696753 | K11: =cbo_debt_gdp!DB16 -> #N/A | L11: =cbo_deficit_gdp!CX16 -> 5.5512322 | M11: =cbo_deficit_gdp!CZ16 -> 5.2800571 | N11: =cbo_deficit_gdp!DB16 -> #N/A | O11: =cbo_primary_deficit_gdp!CX16 -> 2.1789883 | P11: =cbo_primary_deficit_gdp!CZ16 -> 1.17731 | Q11: =cbo_primary_deficit_gdp!DB16 -> #N/A | R11: =cbo_revenues_gdp!CX16 -> 19.066148 | S11: =cbo_revenues_gdp!CZ16 -> 19.407777 | T11: =cbo_revenues_gdp!DB16 -> #N/A | U11: =cbo_outlays_gdp!CX16 -> 24.61738 | V11: =cbo_outlays_gdp!CZ16 -> 24.687834 | W11: =cbo_outlays_gdp!DB16 -> #N/A | X11: =cbo_interest_gdp!CX16 -> 3.3722438 | Y11: =cbo_interest_gdp!CZ16 -> 4.1027471 | Z11: =cbo_interest_gdp!DB16 -> #N/A | AA11: =cbo_rgdp!CX16 -> 4.1 | AB11: =cbo_rgdp!CZ16 -> 3.4 | AC11: =cbo_rgdp!DB16 -> #N/A | AD11: =IFERROR(IFERROR(VLOOKUP(A11,frbus_infl!$B$7:$H$1000,7,FALSE),VLOOKUP(A11,frbus_infl!$C$7:$H$1000,6,FALSE)),VLOOKUP(A11,frbus_infl!$D$7:$H$1000,5,FALSE)) -> 4.9533898 | AE11: =IFERROR(IFERROR(VLOOKUP(A11,frbus_infl!$B$7:$I$1000,8,FALSE),VLOOKUP(A11,frbus_infl!$C$7:$I$1000,7,FALSE)),VLOOKUP(A11,frbus_infl!$D$7:$I$1000,6,FALSE)) -> #N/A | AF11: =IFERROR(IFERROR(VLOOKUP(A11,frbus_infl!$B$7:$I$1000,5,FALSE),VLOOKUP(A11,frbus_infl!$C$7:$I$1000,4,FALSE)),VLOOKUP(A11,frbus_infl!$D$7:$I$1000,3,FALSE)) -> 4.35 | AG11: =IFERROR(IFERROR(VLOOKUP(A11,treas_holdings!$B$7:$I$1000,7,FALSE),VLOOKUP(A11,treas_holdings!$C$7:$I$1000,6,FALSE)),VLOOKUP(A11,treas_holdings!$D$7:$I$1000,5,FALSE)) -> 3.8055647 | AH11: =IFERROR(IFERROR(VLOOKUP(A11,treas_holdings!$B$7:$I$1000,8,FALSE),VLOOKUP(A11,treas_holdings!$C$7:$I$1000,7,FALSE)),VLOOKUP(A11,treas_holdings!$D$7:$I$1000,6,FALSE)) -> 3.0965675 | AI11: =IFERROR(IFERROR(VLOOKUP(A11,divyield!$B$7:$E$1001,4,FALSE),VLOOKUP(A11,divyield!$C$7:$E$1001,3,FALSE)),VLOOKUP(A11,divyield!$D$7:$E$1001,2,FALSE)) -> 5.9128204 | AJ11: =VLOOKUP(A11,ffr!$B$6:$C$1000,2) -> 8.74 | AK11: =VLOOKUP(A11,dkw!$B$7:$H$1001,3,FALSE) -> 12.1911 | AL11: =VLOOKUP(A11,dkw!$B$7:$H$1001,4,FALSE) -> 3.7849 | AM11: =VLOOKUP(A11,dkw!$B$7:$H$1001,5,FALSE) -> 3.4662 | AN11: =VLOOKUP(A11,dkw!$B$7:$H$1001,6,FALSE) -> 4.0128 | AO11: =VLOOKUP(A11,dkw!$B$7:$H$1001,7,FALSE) -> 0.9272 | AP11: =VLOOKUP(A11,acm!B$7:E$1001,2,FALSE) -> 11.80212 | AQ11: =VLOOKUP(A11,acm!B$7:E$1001,3,FALSE) -> 4.37507 | AR11: =VLOOKUP(A11,acm!B$7:E$1001,4,FALSE) -> 7.42705 | AS11: =VLOOKUP(A11,cr!B$7:F$1001,5,FALSE) -> #N/A | AT11: =VLOOKUP(A11,cr!B$7:F$1001,4,FALSE) -> #N/A | AU11: =VLOOKUP(A11,cr!B$7:F$1001,2,FALSE) -> #N/A
A12: 31260 | B12: 11 | C12: =VLOOKUP(A12,treasuries_zc!$B$7:$J$1000,_xlfn.XMATCH(C$1,treasuries_zc!$B$1:$J$1,1),FALSE) -> 10.855752 | D12: =VLOOKUP(A12,treasuries_zc!$B$7:$J$1000,_xlfn.XMATCH(D$1,treasuries_zc!$B$1:$J$1,1),FALSE) -> 11.712831 | E12: =VLOOKUP(A12,treasuries_zc!$B$7:$J$1000,_xlfn.XMATCH(E$1,treasuries_zc!$B$1:$J$1,1),FALSE) -> 11.283467 | F12: =VLOOKUP(A12,treasuries_zc!$B$7:$J$1000,_xlfn.XMATCH(F$1,treasuries_zc!$B$1:$J$1,1),FALSE) -> 10.3673 | G12: =VLOOKUP(A12,treasuries_zc!$B$7:$J$1000,_xlfn.XMATCH(G$1,treasuries_zc!$B$1:$J$1,1),FALSE) -> 10.7977 | H12: =VLOOKUP(A12,treasuries_zc!$B$7:$J$1000,_xlfn.XMATCH(H$1,treasuries_zc!$B$1:$J$1,1),FALSE) -> 11.1216 | I12: =cbo_debt_gdp!CX17 -> 39.635417 | J12: =cbo_debt_gdp!CZ17 -> 40.235841 | K12: =cbo_debt_gdp!DB17 -> #N/A | L12: =cbo_deficit_gdp!CX17 -> 5.46875 | M12: =cbo_deficit_gdp!CZ17 -> 2.1440057 | N12: =cbo_deficit_gdp!DB17 -> #N/A | O12: =cbo_primary_deficit_gdp!CX17 -> 2.109375 | P12: =cbo_primary_deficit_gdp!CZ17 -> -1.0362694 | Q12: =cbo_primary_deficit_gdp!DB17 -> #N/A | R12: =cbo_revenues_gdp!CX17 -> 19.192708 | S12: =cbo_revenues_gdp!CZ17 -> 19.546185 | T12: =cbo_revenues_gdp!DB17 -> #N/A | U12: =cbo_outlays_gdp!CX17 -> 24.635417 | V12: =cbo_outlays_gdp!CZ17 -> 21.690191 | W12: =cbo_outlays_gdp!DB17 -> #N/A | X12: =cbo_interest_gdp!CX17 -> 3.359375 | Y12: =cbo_interest_gdp!CZ17 -> 3.1802751 | Z12: =cbo_interest_gdp!DB17 -> #N/A | AA12: =cbo_rgdp!CX17 -> 3.3 | AB12: =cbo_rgdp!CZ17 -> 3.5 | AC12: =cbo_rgdp!DB17 -> #N/A | AD12: =IFERROR(IFERROR(VLOOKUP(A12,frbus_infl!$B$7:$H$1000,7,FALSE),VLOOKUP(A12,frbus_infl!$C$7:$H$1000,6,FALSE)),VLOOKUP(A12,frbus_infl!$D$7:$H$1000,5,FALSE)) -> 5.295 | AE12: =IFERROR(IFERROR(VLOOKUP(A12,frbus_infl!$B$7:$I$1000,8,FALSE),VLOOKUP(A12,frbus_infl!$C$7:$I$1000,7,FALSE)),VLOOKUP(A12,frbus_infl!$D$7:$I$1000,6,FALSE)) -> #N/A | AF12: =IFERROR(IFERROR(VLOOKUP(A12,frbus_infl!$B$7:$I$1000,5,FALSE),VLOOKUP(A12,frbus_infl!$C$7:$I$1000,4,FALSE)),VLOOKUP(A12,frbus_infl!$D$7:$I$1000,3,FALSE)) -> #N/A | AG12: =IFERROR(IFERROR(VLOOKUP(A12,treas_holdings!$B$7:$I$1000,7,FALSE),VLOOKUP(A12,treas_holdings!$C$7:$I$1000,6,FALSE)),VLOOKUP(A12,treas_holdings!$D$7:$I$1000,5,FALSE)) -> 3.868469 | AH12: =IFERROR(IFERROR(VLOOKUP(A12,treas_holdings!$B$7:$I$1000,8,FALSE),VLOOKUP(A12,treas_holdings!$C$7:$I$1000,7,FALSE)),VLOOKUP(A12,treas_holdings!$D$7:$I$1000,6,FALSE)) -> 3.1760509 | AI12: =IFERROR(IFERROR(VLOOKUP(A12,divyield!$B$7:$E$1001,4,FALSE),VLOOKUP(A12,divyield!$C$7:$E$1001,3,FALSE)),VLOOKUP(A12,divyield!$D$7:$E$1001,2,FALSE)) -> 6.21857 | AJ12: =VLOOKUP(A12,ffr!$B$6:$C$1000,2) -> 7.8 | AK12: =VLOOKUP(A12,dkw!$B$7:$H$1001,3,FALSE) -> 10.9306 | AL12: =VLOOKUP(A12,dkw!$B$7:$H$1001,4,FALSE) -> 3.2562 | AM12: =VLOOKUP(A12,dkw!$B$7:$H$1001,5,FALSE) -> 3.0924 | AN12: =VLOOKUP(A12,dkw!$B$7:$H$1001,6,FALSE) -> 3.7618 | AO12: =VLOOKUP(A12,dkw!$B$7:$H$1001,7,FALSE) -> 0.8202 | AP12: =VLOOKUP(A12,acm!B$7:E$1001,2,FALSE) -> 10.35384 | AQ12: =VLOOKUP(A12,acm!B$7:E$1001,3,FALSE) -> 3.91385 | AR12: =VLOOKUP(A12,acm!B$7:E$1001,4,FALSE) -> 6.44 | AS12: =VLOOKUP(A12,cr!B$7:F$1001,5,FALSE) -> #N/A | AT12: =VLOOKUP(A12,cr!B$7:F$1001,4,FALSE) -> #N/A | AU12: =VLOOKUP(A12,cr!B$7:F$1001,2,FALSE) -> #N/A
A13: 31444 | B13: 12 | C13: =VLOOKUP(A13,treasuries_zc!$B$7:$J$1000,_xlfn.XMATCH(C$1,treasuries_zc!$B$1:$J$1,1),FALSE) -> 8.4816266 | D13: =VLOOKUP(A13,treasuries_zc!$B$7:$J$1000,_xlfn.XMATCH(D$1,treasuries_zc!$B$1:$J$1,1),FALSE) -> 8.8632668 | E13: =VLOOKUP(A13,treasuries_zc!$B$7:$J$1000,_xlfn.XMATCH(E$1,treasuries_zc!$B$1:$J$1,1),FALSE) -> 8.6722792 | F13: =VLOOKUP(A13,treasuries_zc!$B$7:$J$1000,_xlfn.XMATCH(F$1,treasuries_zc!$B$1:$J$1,1),FALSE) -> 8.2209 | G13: =VLOOKUP(A13,treasuries_zc!$B$7:$J$1000,_xlfn.XMATCH(G$1,treasuries_zc!$B$1:$J$1,1),FALSE) -> 8.3002 | H13: =VLOOKUP(A13,treasuries_zc!$B$7:$J$1000,_xlfn.XMATCH(H$1,treasuries_zc!$B$1:$J$1,1),FALSE) -> 8.6938 | I13: =cbo_debt_gdp!CX18 -> 41.030534 | J13: =cbo_debt_gdp!CZ18 -> 40.168679 | K13: =cbo_debt_gdp!DB18 -> #N/A | L13: =cbo_deficit_gdp!CX18 -> 4.9618321 | M13: =cbo_deficit_gdp!CZ18 -> 1.7198611 | N13: =cbo_deficit_gdp!DB18 -> #N/A | O13: =cbo_primary_deficit_gdp!CX18 -> 1.6555344 | P13: =cbo_primary_deficit_gdp!CZ18 -> -0.93104019 | Q13: =cbo_primary_deficit_gdp!DB18 -> #N/A | R13: =cbo_revenues_gdp!CX18 -> 18.55916 | S13: =cbo_revenues_gdp!CZ18 -> 18.918472 | T13: =cbo_revenues_gdp!DB18 -> #N/A | U13: =cbo_outlays_gdp!CX18 -> 23.520992 | V13: =cbo_outlays_gdp!CZ18 -> 20.638333 | W13: =cbo_outlays_gdp!DB18 -> #N/A | X13: =cbo_interest_gdp!CX18 -> 3.3062977 | Y13: =cbo_interest_gdp!CZ18 -> 2.6509013 | Z13: =cbo_interest_gdp!DB18 -> #N/A | AA13: =cbo_rgdp!CX18 -> 3 | AB13: =cbo_rgdp!CZ18 -> 3.4 | AC13: =cbo_rgdp!DB18 -> #N/A | AD13: =IFERROR(IFERROR(VLOOKUP(A13,frbus_infl!$B$7:$H$1000,7,FALSE),VLOOKUP(A13,frbus_infl!$C$7:$H$1000,6,FALSE)),VLOOKUP(A13,frbus_infl!$D$7:$H$1000,5,FALSE)) -> 4.8771181 | AE13: =IFERROR(IFERROR(VLOOKUP(A13,frbus_infl!$B$7:$I$1000,8,FALSE),VLOOKUP(A13,frbus_infl!$C$7:$I$1000,7,FALSE)),VLOOKUP(A13,frbus_infl!$D$7:$I$1000,6,FALSE)) -> #N/A | AF13: =IFERROR(IFERROR(VLOOKUP(A13,frbus_infl!$B$7:$I$1000,5,FALSE),VLOOKUP(A13,frbus_infl!$C$7:$I$1000,4,FALSE)),VLOOKUP(A13,frbus_infl!$D$7:$I$1000,3,FALSE)) -> 4 | AG13: =IFERROR(IFERROR(VLOOKUP(A13,treas_holdings!$B$7:$I$1000,7,FALSE),VLOOKUP(A13,treas_holdings!$C$7:$I$1000,6,FALSE)),VLOOKUP(A13,treas_holdings!$D$7:$I$1000,5,FALSE)) -> 3.9180106 | AH13: =IFERROR(IFERROR(VLOOKUP(A13,treas_holdings!$B$7:$I$1000,8,FALSE),VLOOKUP(A13,treas_holdings!$C$7:$I$1000,7,FALSE)),VLOOKUP(A13,treas_holdings!$D$7:$I$1000,6,FALSE)) -> 3.1428381 | AI13: =IFERROR(IFERROR(VLOOKUP(A13,divyield!$B$7:$E$1001,4,FALSE),VLOOKUP(A13,divyield!$C$7:$E$1001,3,FALSE)),VLOOKUP(A13,divyield!$D$7:$E$1001,2,FALSE)) -> 4.6626305 | AJ13: =VLOOKUP(A13,ffr!$B$6:$C$1000,2) -> 7.95 | AK13: =VLOOKUP(A13,dkw!$B$7:$H$1001,3,FALSE) -> 8.4921 | AL13: =VLOOKUP(A13,dkw!$B$7:$H$1001,4,FALSE) -> 2.5938 | AM13: =VLOOKUP(A13,dkw!$B$7:$H$1001,5,FALSE) -> 2.0129 | AN13: =VLOOKUP(A13,dkw!$B$7:$H$1001,6,FALSE) -> 3.4265 | AO13: =VLOOKUP(A13,dkw!$B$7:$H$1001,7,FALSE) -> 0.4589 | AP13: =VLOOKUP(A13,acm!B$7:E$1001,2,FALSE) -> 8.21614 | AQ13: =VLOOKUP(A13,acm!B$7:E$1001,3,FALSE) -> 2.30003 | AR13: =VLOOKUP(A13,acm!B$7:E$1001,4,FALSE) -> 5.9161 | AS13: =VLOOKUP(A13,cr!B$7:F$1001,5,FALSE) -> #N/A | AT13: =VLOOKUP(A13,cr!B$7:F$1001,4,FALSE) -> #N/A | AU13: =VLOOKUP(A13,cr!B$7:F$1001,2,FALSE) -> #N/A
... A96: 45658 | B96: 95 | C96: =VLOOKUP(A96,treasuries_zc!$B$7:$J$1000,_xlfn.XMATCH(C$1,treasuries_zc!$B$1:$J$1,1),FALSE) -> 4.8528212 | D96: =VLOOKUP(A96,treasuries_zc!$B$7:$J$1000,_xlfn.XMATCH(D$1,treasuries_zc!$B$1:$J$1,1),FALSE) -> 5.1319072 | E96: =VLOOKUP(A96,treasuries_zc!$B$7:$J$1000,_xlfn.XMATCH(E$1,treasuries_zc!$B$1:$J$1,1),FALSE) -> 4.9922715 | F96: =VLOOKUP(A96,treasuries_zc!$B$7:$J$1000,_xlfn.XMATCH(F$1,treasuries_zc!$B$1:$J$1,1),FALSE) -> 4.5976 | G96: =VLOOKUP(A96,treasuries_zc!$B$7:$J$1000,_xlfn.XMATCH(G$1,treasuries_zc!$B$1:$J$1,1),FALSE) -> 4.6405 | H96: =VLOOKUP(A96,treasuries_zc!$B$7:$J$1000,_xlfn.XMATCH(H$1,treasuries_zc!$B$1:$J$1,1),FALSE) -> 5.0367 | I96: =cbo_debt_gdp!CX101 -> 99.890496 | J96: =cbo_debt_gdp!CZ101 -> 109.2158 | K96: =cbo_debt_gdp!DB101 -> 118.48143 | L96: =cbo_deficit_gdp!CX101 -> 6.1886116 | M96: =cbo_deficit_gdp!CZ101 -> 5.8800901 | N96: =cbo_deficit_gdp!DB101 -> 5.7606519 | O96: =cbo_primary_deficit_gdp!CX101 -> 3.0295992 | P96: =cbo_primary_deficit_gdp!CZ101 -> 2.231137 | Q96: =cbo_primary_deficit_gdp!DB101 -> 1.7024763 | R96: =cbo_revenues_gdp!CX101 -> 17.132333 | S96: =cbo_revenues_gdp!CZ101 -> 17.994724 | T96: =cbo_revenues_gdp!DB101 -> 18.27886 | U96: =cbo_outlays_gdp!CX101 -> 23.320945 | V96: =cbo_outlays_gdp!CZ101 -> 23.874815 | W96: =cbo_outlays_gdp!DB101 -> 24.041788 | X96: =cbo_interest_gdp!CX101 -> 3.1590125 | Y96: =cbo_interest_gdp!CZ101 -> 3.6489531 | Z96: =cbo_interest_gdp!DB101 -> 4.0581755 | AA96: =cbo_rgdp!CX101 -> 2.234 | AB96: =cbo_rgdp!CZ101 -> 1.817 | AC96: =cbo_rgdp!DB101 -> 1.768 | AD96: =IFERROR(IFERROR(VLOOKUP(A96,frbus_infl!$B$7:$H$1000,7,FALSE),VLOOKUP(A96,frbus_infl!$C$7:$H$1000,6,FALSE)),VLOOKUP(A96,frbus_infl!$D$7:$H$1000,5,FALSE)) -> 2.11 | AE96: =IFERROR(IFERROR(VLOOKUP(A96,frbus_infl!$B$7:$I$1000,8,FALSE),VLOOKUP(A96,frbus_infl!$C$7:$I$1000,7,FALSE)),VLOOKUP(A96,frbus_infl!$D$7:$I$1000,6,FALSE)) -> 2.2000977 | AF96: =IFERROR(IFERROR(VLOOKUP(A96,frbus_infl!$B$7:$I$1000,5,FALSE),VLOOKUP(A96,frbus_infl!$C$7:$I$1000,4,FALSE)),VLOOKUP(A96,frbus_infl!$D$7:$I$1000,3,FALSE)) -> 2.3 | AG96: =IFERROR(IFERROR(VLOOKUP(A96,treas_holdings!$B$7:$I$1000,7,FALSE),VLOOKUP(A96,treas_holdings!$C$7:$I$1000,6,FALSE)),VLOOKUP(A96,treas_holdings!$D$7:$I$1000,5,FALSE)) -> 12.756076 | AH96: =IFERROR(IFERROR(VLOOKUP(A96,treas_holdings!$B$7:$I$1000,8,FALSE),VLOOKUP(A96,treas_holdings!$C$7:$I$1000,7,FALSE)),VLOOKUP(A96,treas_holdings!$D$7:$I$1000,6,FALSE)) -> 13.065784 | AI96: =IFERROR(IFERROR(VLOOKUP(A96,divyield!$B$7:$E$1001,4,FALSE),VLOOKUP(A96,divyield!$C$7:$E$1001,3,FALSE)),VLOOKUP(A96,divyield!$D$7:$E$1001,2,FALSE)) -> 2.4668563 | AJ96: =VLOOKUP(A96,ffr!$B$6:$C$1000,2) -> 4.33 | AK96: =VLOOKUP(A96,dkw!$B$7:$H$1001,3,FALSE) -> 4.8785 | AL96: =VLOOKUP(A96,dkw!$B$7:$H$1001,4,FALSE) -> 1.307 | AM96: =VLOOKUP(A96,dkw!$B$7:$H$1001,5,FALSE) -> 0.7216 | AN96: =VLOOKUP(A96,dkw!$B$7:$H$1001,6,FALSE) -> 2.7974 | AO96: =VLOOKUP(A96,dkw!$B$7:$H$1001,7,FALSE) -> 0.0525 | AP96: =VLOOKUP(A96,acm!B$7:E$1001,2,FALSE) -> 4.5945 | AQ96: =VLOOKUP(A96,acm!B$7:E$1001,3,FALSE) -> 0.50232 | AR96: =VLOOKUP(A96,acm!B$7:E$1001,4,FALSE) -> 4.09218 | AS96: =VLOOKUP(A96,cr!B$7:F$1001,5,FALSE) -> 3.1115327 | AT96: =VLOOKUP(A96,cr!B$7:F$1001,4,FALSE) -> 1.2112 | AU96: =VLOOKUP(A96,cr!B$7:F$1001,2,FALSE) -> 3.3864

Sheet treasuries_zc
B1: date | C1: i15y_zcm | D1: i10y_zcm | E1: i5y_zcm | F1: i5y3m_zcm | G1: i10y3m_zcm | H1: i5y5y_zcm | I1: i10y5y_zcm | J1: i5y10y_zcm | N1: Source
A2: 197501 !M | B2: .excel_first | C2: FYCCZFE@USECON | D2: FYCCZAE@USECON | E2: FYCCZ5E@USECON | F2: FZ3M5YE@USECON | G2: FZ3M10E@USECON | N2: https://www.federalreserve.gov/data/nominal-yield-curve.htm
A3: .DESC | C3: US Treasury Yield: Continuously Compounded Zero-Coupon: 15-Yrs(EOP, %) | D3: US Treasury Yield: Continuously Compounded Zero-Coupon: 10-Yrs(EOP, %) | E3: US Treasury Yield: Continuously Compounded Zero-Coupon: 5-Yrs(EOP, %) | F3: US Treas Yld: Cont Compounded Fwd Rate Beg 5 Yrs Hence: 3-Month(EOP, % p.a.) | G3: US Treas Yld: Cont Compounded Fwd Rate Beg 10 Yrs Hence: 3-Mo (EOP, % p.a.) | N3: Mnemonic: SVENYXX
A4: .DTLM | C4: Dec-02-2025 14:13 | D4: Dec-02-2025 14:13 | E4: Dec-02-2025 14:13 | F4: Dec-02-2025 14:22 | G4: Dec-02-2025 14:22
A5: .SOURCE | C5: FRB | D5: FRB | E5: FRB | F5: HAVER | G5: HAVER
A6: .AGG | C6: End of Period | D6: End of Period | E6: End of Period | F6: End of Period | G6: End of Period
A7: 197501 | B7: 27395 | C7: 7.3326 | D7: 7.2796 | E7: 7.1207 | F7: 7.4385 | G7: 7.4386 | H7: =100*((((1+D7/100)^10)/(1+E7/100)^5)^(1/5)-1) -> 7.4387357 | I7: =100*((((1+C7/100)^15)/(1+D7/100)^10)^(1/5)-1) -> 7.4386786 | J7: =100*((((1+C7/100)^15)/(1+E7/100)^5)^(1/10)-1) -> 7.4387071
A8: 197502 | B8: 27426 | C8: 7.3022 | D8: 7.21 | E8: 6.9345 | F8: 7.4805 | G8: 7.4865 | H8: =100*((((1+D8/100)^10)/(1+E8/100)^5)^(1/5)-1) -> 7.4862098 | I8: =100*((((1+C8/100)^15)/(1+D8/100)^10)^(1/5)-1) -> 7.4868379 | J8: =100*((((1+C8/100)^15)/(1+E8/100)^5)^(1/10)-1) -> 7.4865239
A9: 197503 | B9: 27454 | C9: 7.5035 | D9: 7.444 | E9: 7.2657 | F9: 7.6223 | G9: 7.6224 | H9: =100*((((1+D9/100)^10)/(1+E9/100)^5)^(1/5)-1) -> 7.6225964 | I9: =100*((((1+C9/100)^15)/(1+D9/100)^10)^(1/5)-1) -> 7.6225989 | J9: =100*((((1+C9/100)^15)/(1+E9/100)^5)^(1/10)-1) -> 7.6225976
A10: 197504 | B10: 27485 | C10: 8.0136 | D10: 7.9672 | E10: 7.8282 | F10: 8.1062 | G10: 8.1062 | H10: =100*((((1+D10/100)^10)/(1+E10/100)^5)^(1/5)-1) -> 8.1063792 | I10: =100*((((1+C10/100)^15)/(1+D10/100)^10)^(1/5)-1) -> 8.1064598 | J10: =100*((((1+C10/100)^15)/(1+E10/100)^5)^(1/10)-1) -> 8.1064195
A11: 197505 | B11: 27515 | C11: 7.7659 | D11: 7.686 | E11: 7.4464 | F11: 7.925 | G11: 7.9257 | H11: =100*((((1+D11/100)^10)/(1+E11/100)^5)^(1/5)-1) -> 7.9261343 | I11: =100*((((1+C11/100)^15)/(1+D11/100)^10)^(1/5)-1) -> 7.9258779 | J11: =100*((((1+C11/100)^15)/(1+E11/100)^5)^(1/10)-1) -> 7.9260061
A12: 197506 | B12: 27546 | C12: 7.6313 | D12: 7.6212 | E12: 7.5322 | F12: 7.7809 | G12: 7.6624 | H12: =100*((((1+D12/100)^10)/(1+E12/100)^5)^(1/5)-1) -> 7.7102737 | I12: =100*((((1+C12/100)^15)/(1+D12/100)^10)^(1/5)-1) -> 7.6515028 | J12: =100*((((1+C12/100)^15)/(1+E12/100)^5)^(1/10)-1) -> 7.6808842
A13: 197507 | B13: 27576 | C13: 7.6778 | D13: 7.7142 | E13: 7.7762 | F13: 7.7448 | G13: 7.6095 | H13: =100*((((1+D13/100)^10)/(1+E13/100)^5)^(1/5)-1) -> 7.6522357 | I13: =100*((((1+C13/100)^15)/(1+D13/100)^10)^(1/5)-1) -> 7.6050369 | J13: =100*((((1+C13/100)^15)/(1+E13/100)^5)^(1/10)-1) -> 7.6286337
A14: 197508 | B14: 27607 | C14: 7.8987 | D14: 7.9025 | E14: 7.895 | F14: 7.9519 | G14: 7.8925 | H14: =100*((((1+D14/100)^10)/(1+E14/100)^5)^(1/5)-1) -> 7.9100005 | I14: =100*((((1+C14/100)^15)/(1+D14/100)^10)^(1/5)-1) -> 7.8911004 | J14: =100*((((1+C14/100)^15)/(1+E14/100)^5)^(1/10)-1) -> 7.90055
A15: 197509 | B15: 27638 | C15: 8.1318 | D15: 8.1502 | E15: 8.1755 | F15: 8.1904 | G15: 8.0972 | H15: =100*((((1+D15/100)^10)/(1+E15/100)^5)^(1/5)-1) -> 8.1249059 | I15: =100*((((1+C15/100)^15)/(1+D15/100)^10)^(1/5)-1) -> 8.0950094 | J15: =100*((((1+C15/100)^15)/(1+E15/100)^5)^(1/10)-1) -> 8.1099566
A16: 197510 | B16: 27668 | C16: 7.833 | D16: 7.7593 | E16: 7.5381 | F16: 7.98 | G16: 7.9805 | H16: =100*((((1+D16/100)^10)/(1+E16/100)^5)^(1/5)-1) -> 7.980955 | I16: =100*((((1+C16/100)^15)/(1+D16/100)^10)^(1/5)-1) -> 7.9805513 | J16: =100*((((1+C16/100)^15)/(1+E16/100)^5)^(1/10)-1) -> 7.9807531
A17: 197511 | B17: 27699 | C17: 7.9981 | D17: 7.9271 | E17: 7.7131 | F17: 8.1419 | G17: 8.1401 | H17: =100*((((1+D17/100)^10)/(1+E17/100)^5)^(1/5)-1) -> 8.1415252 | I17: =100*((((1+C17/100)^15)/(1+D17/100)^10)^(1/5)-1) -> 8.1402402 | J17: =100*((((1+C17/100)^15)/(1+E17/100)^5)^(1/10)-1) -> 8.1408827
A18: 197512 | B18: 27729 | C18: 7.742 | D18: 7.6472 | E18: 7.3657 | F18: 7.9177 | G18: 7.9315 | H18: =100*((((1+D18/100)^10)/(1+E18/100)^5)^(1/5)-1) -> 7.9294381 | I18: =100*((((1+C18/100)^15)/(1+D18/100)^10)^(1/5)-1) -> 7.9318505 | J18: =100*((((1+C18/100)^15)/(1+E18/100)^5)^(1/10)-1) -> 7.9306443
... A171: 198809 | B171: 32387 | C171: 9.0343 | D171: 8.8704 | E171: 8.5027 | F171: 8.9435 | G171: 9.4092 | H171: =100*((((1+D171/100)^10)/(1+E171/100)^5)^(1/5)-1) -> 9.2393461 | I171: =100*((((1+C171/100)^15)/(1+D171/100)^10)^(1/5)-1) -> 9.3628406 | J171: =100*((((1+C171/100)^15)/(1+E171/100)^5)^(1/10)-1) -> 9.3010759
A172: 198810 | B172: 32417 | C172: 8.841 | D172: 8.6762 | E172: 8.2532 | F172: 8.7227 | G172: 9.2921 | H172: =100*(((1+D172/100)^10/(1+E172/100)^5)^(1/5)-1) -> 9.1008529 | I172: =100*(((1+C172/100)^15/(1+D172/100)^10)^(1/5)-1) -> 9.1713501 | J172: =100*((((1+C172/100)^15)/(1+E172/100)^5)^(1/10)-1) -> 9.1360958
A173: 198811 | B173: 32448 | C173: 9.0656 | D173: 8.9978 | E173: 8.7723 | F173: 9.0429 | G173: 9.2925 | H173: =100*(((1+D173/100)^10/(1+E173/100)^5)^(1/5)-1) -> 9.2237675 | I173: =100*(((1+C173/100)^15/(1+D173/100)^10)^(1/5)-1) -> 9.2013265 | J173: =100*((((1+C173/100)^15)/(1+E173/100)^5)^(1/10)-1) -> 9.2125464
A174: 198812 | B174: 32478 | C174: 8.9112 | D174: 9.0064 | E174: 9.0037 | F174: 9.0908 | G174: 8.8659 | H174: =100*(((1+D174/100)^10/(1+E174/100)^5)^(1/5)-1) -> 9.0091001 | I174: =100*(((1+C174/100)^15/(1+D174/100)^10)^(1/5)-1) -> 8.7210494 | J174: =100*((((1+C174/100)^15)/(1+E174/100)^5)^(1/10)-1) -> 8.8649794
A175: 198901 | B175: 32509 | C175: 8.7202 | D175: 8.827 | E175: 8.8862 | F175: 8.8538 | G175: 8.6341 | H175: =100*(((1+D175/100)^10/(1+E175/100)^5)^(1/5)-1) -> 8.7678322 | I175: =100*(((1+C175/100)^15/(1+D175/100)^10)^(1/5)-1) -> 8.5069143 | J175: =100*((((1+C175/100)^15)/(1+E175/100)^5)^(1/10)-1) -> 8.6372949
A176: 198902 | B176: 32540 | C176: 9.0182 | D176: 9.1471 | E176: 9.2516 | F176: 9.1566 | G176: 8.8884 | H176: =100*(((1+D176/100)^10/(1+E176/100)^5)^(1/5)-1) -> 9.0427 | I176: =100*(((1+C176/100)^15/(1+D176/100)^10)^(1/5)-1) -> 8.7608565 | J176: =100*((((1+C176/100)^15)/(1+E176/100)^5)^(1/10)-1) -> 8.9016871
A177: 198903 | B177: 32568 | C177: 8.9269 | D177: 9.0739 | E177: 9.3174 | F177: 9.0057 | G177: 8.6881 | H177: =100*(((1+D177/100)^10/(1+E177/100)^5)^(1/5)-1) -> 8.8309424 | I177: =100*(((1+C177/100)^15/(1+D177/100)^10)^(1/5)-1) -> 8.6334941 | J177: =100*((((1+C177/100)^15)/(1+E177/100)^5)^(1/10)-1) -> 8.7321734
A178: 198904 | B178: 32599 | C178: 8.8299 | D178: 8.9012 | E178: 8.919 | F178: 8.8929 | G178: 8.8071 | H178: =100*(((1+D178/100)^10/(1+E178/100)^5)^(1/5)-1) -> 8.8834029 | I178: =100*(((1+C178/100)^15/(1+D178/100)^10)^(1/5)-1) -> 8.68744 | J178: =100*((((1+C178/100)^15)/(1+E178/100)^5)^(1/10)-1) -> 8.7853773
A179: 198905 | B179: 32629 | C179: 8.4762 | D179: 8.5151 | E179: 8.5565 | F179: 8.499 | G179: 8.4346 | H179: =100*(((1+D179/100)^10/(1+E179/100)^5)^(1/5)-1) -> 8.4737158 | I179: =100*(((1+C179/100)^15/(1+D179/100)^10)^(1/5)-1) -> 8.3984418 | J179: =100*((((1+C179/100)^15)/(1+E179/100)^5)^(1/10)-1) -> 8.4360723
A180: 198906 | B180: 32660 | C180: 8.0516 | D180: 8.0823 | E180: 7.9783 | F180: 8.1601 | G180: 8.1241 | H180: =100*(((1+D180/100)^10/(1+E180/100)^5)^(1/5)-1) -> 8.1864002 | I180: =100*(((1+C180/100)^15/(1+D180/100)^10)^(1/5)-1) -> 7.9902262 | J180: =100*((((1+C180/100)^15)/(1+E180/100)^5)^(1/10)-1) -> 8.0882687
A181: 198907 | B181: 32690 | C181: 7.9014 | D181: 7.7831 | E181: 7.5167 | F181: 7.8407 | G181: 8.1675 | H181: =100*(((1+D181/100)^10/(1+E181/100)^5)^(1/5)-1) -> 8.0501601 | I181: =100*(((1+C181/100)^15/(1+D181/100)^10)^(1/5)-1) -> 8.1383897 | J181: =100*((((1+C181/100)^15)/(1+E181/100)^5)^(1/10)-1) -> 8.0942659
A182: 198908 | B182: 32721 | C182: 8.1611 | D182: 8.1871 | E182: 8.1794 | F182: 8.1978 | G182: 8.1615 | H182: =100*(((1+D182/100)^10/(1+E182/100)^5)^(1/5)-1) -> 8.1948005 | I182: =100*(((1+C182/100)^15/(1+D182/100)^10)^(1/5)-1) -> 8.1091187 | J182: =100*((((1+C182/100)^15)/(1+E182/100)^5)^(1/10)-1) -> 8.1519512
A183: 198909 | B183: 32752 | C183: 8.2042 | D183: 8.2513 | E183: 8.2656 | F183: 8.2792 | G183: 8.1712 | H183: =100*(((1+D183/100)^10/(1+E183/100)^5)^(1/5)-1) -> 8.2370019 | I183: =100*(((1+C183/100)^15/(1+D183/100)^10)^(1/5)-1) -> 8.1100615 | J183: =100*((((1+C183/100)^15)/(1+E183/100)^5)^(1/10)-1) -> 8.1735131
... A617: 202511 | B617: 45962 | C617: 4.5139 | D617: 4.0983 | E617: 3.5787 | F617: 4.0508 | G617: 5.1194 | H617: =100*(((1+D617/100)^10/(1+E617/100)^5)^(1/5)-1) -> 4.6205066 | I617: =100*(((1+C617/100)^15/(1+D617/100)^10)^(1/5)-1) -> 5.3500843 | J617: =100*((((1+C617/100)^15)/(1+E617/100)^5)^(1/10)-1) -> 4.9846617

Sheet cbo_debt
C1: 1976A | D1: 1976B | E1: 1977A | F1: 1979A | G1: 1980A | H1: 1981A | I1: 1982A | J1: 1983A | K1: 1984A | L1: 1985A | M1: 1985B | N1: 1986A | O1: 1986B | P1: 1987A | Q1: 1987B | R1: 1988A | S1: 1988B | T1: 1989A | U1: 1989B | V1: 1990A | W1: 1990B | X1: 1991A | Y1: 1991B | Z1: 1992A | AA1: 1992B | AB1: 1993A | AC1: 1993B | AD1: 1994A | AE1: 1994B | AF1: 1995A | AG1: 1995B | AH1: 1995C | AI1: 1996A | AJ1: 1997A | AK1: 1997B | AL1: 1998A | AM1: 1998B | AN1: 1999A | AO1: 1999B | AP1: 2000A | AQ1: 2000B | AR1: 2001A | AS1: 2001B | AT1: 2002A | AU1: 2002B | AV1: 2003A | AW1: 2003B | AX1: 2004A | AY1: 2004B | AZ1: 2005A | BA1: 2005B | BB1: 2006A | BC1: 2006B | BD1: 2007A | BE1: 2007B | BF1: 2008A | BG1: 2008B | BH1: 2009A | BI1: 2009B | BJ1: 2009C | BK1: 2010A | BL1: 2010B | BM1: 2011A | BN1: 2011B | BO1: 2012A | BP1: 2012B | BQ1: 2012C | BR1: 2013A | BS1: 2013B | BT1: 2014A | BU1: 2014B | BV1: 2014C | BW1: 2015A | BX1: 2015B | BY1: 2015C | BZ1: 2016A | CA1: 2016B | CB1: 2016C | CC1: 2017A | CD1: 2017B | CE1: 2018A | CF1: 2019A | CG1: 2019B | CH1: 2019C | CI1: 2020A | CJ1: 2020B | CK1: 2020C | CL1: 2021A | CM1: 2021B | CN1: 2022A | CO1: 2023A | CP1: 2023B | CQ1: 2024A | CR1: 2024B | CS1: 2025A
A2: 1975 2035 !A | B2: .excel_first | AU2: CADAL02B@GOVFIN | AW2: CADAL03B@GOVFIN | AX2: CADAL04A@GOVFIN | AY2: CADAL04B@GOVFIN | AZ2: CADAL05A@GOVFIN | BA2: CADAL05B@GOVFIN | BB2: CADAL06A@GOVFIN | BC2: CADAL06B@GOVFIN | BD2: CADAL07A@GOVFIN | BE2: CADAL07B@GOVFIN | BF2: CADAL08A@GOVFIN | BG2: CADAL08B@GOVFIN | BH2: CADAL09A@GOVFIN | BJ2: CADAL09B@GOVFIN | BK2: CADAL10A@GOVFIN | BL2: CADAL10B@GOVFIN | BM2: CADAL11A@GOVFIN | BN2: CADAL11B@GOVFIN | BO2: CADAL12A@GOVFIN | BP2: CADAL12B@GOVFIN | BQ2: CADAL12C@GOVFIN | BR2: CADAL13A@GOVFIN | BS2: CADAL13B@GOVFIN | BT2: CADAL14A@GOVFIN | BU2: CADAL14B@GOVFIN | BV2: CADAL14C@GOVFIN | BW2: CADAL15A@GOVFIN | BX2: CADAL15B@GOVFIN | BY2: CADAL15C@GOVFIN | BZ2: CADAL16A@GOVFIN | CA2: CADAL16B@GOVFIN | CB2: CADAL16C@GOVFIN | CC2: CADAL17A@GOVFIN | CD2: CADAL17B@GOVFIN | CE2: CADAL18A@GOVFIN | CF2: CADAL19A@GOVFIN | CG2: CADAL19B@GOVFIN | CH2: CADAL19C@GOVFIN | CI2: CADAL20A@GOVFIN | CJ2: CADAL20B@GOVFIN | CK2: CADAL20C@GOVFIN | CL2: CADAL21A@GOVFIN | CM2: CADAL21B@GOVFIN | CN2: CADAL22A@GOVFIN | CO2: CADAL23A@GOVFIN | CP2: CADAL23B@GOVFIN | CQ2: CADAL24A@GOVFIN | CR2: CADAL24B@GOVFIN | CS2: PDPABUD@GOVFIN
A3: .DESC | C3: Imputed | D3: Imputed | E3: Imputed | F3: Imputed | G3: Imputed | H3: Imputed | I3: Imputed | AU3: CBO Baseline Budget, August 2002: Debt Held by the Public (FY, Bil.$) | AW3: CBO Baseline Budget, August 2003: Debt Held by the Public (FY, Bil.$) | AX3: CBO Baseline Budget, January 2004: Debt Held by the Public (FY, Bil.$) | AY3: CBO Baseline Budget, September 2004: Debt Held by the Public (FY, Bil.$) | AZ3: CBO Baseline Budget, January 2005: Debt Held by the Public (FY, Bil.$) | BA3: CBO Baseline Budget, August 2005: Debt Held by the Public (FY, Bil.$) | BB3: CBO Baseline Budget, January 2006: Debt Held by the Public (FY, Bil.$) | BC3: CBO Baseline Budget, August 2006: Debt Held by the Public (FY, Bil.$) | BD3: CBO Baseline Budget, January 2007: Debt Held by the Public (FY, Bil.$) | BE3: CBO Baseline Budget, August 2007: Debt Held by the Public (FY, Bil.$) | BF3: CBO Baseline Budget, January 2008: Debt Held by the Public (FY, Bil.$) | BG3: CBO Baseline Budget, August 2008: Debt Held by the Public (FY, Bil.$) | BH3: CBO Baseline Budget, January 2009: Debt Held by the Public (FY, Bil.$) | BJ3: CBO Baseline Budget, August 2009: Debt Held by the Public (FY, Bil.$) | BK3: CBO Baseline Budget, January 2010: Debt Held by the Public (FY, Bil.$) | BL3: CBO Baseline Budget, August 2010: Debt Held by the Public (FY, Bil.$) | BM3: CBO Baseline Budget, January 2011: Debt Held by the Public (FY, Bil.$) | BN3: CBO Baseline Budget, August 2011: Debt Held by the Public (FY, Bil.$) | BO3: CBO Baseline Budget, January 2012: Debt Held by the Public (FY, Bil.$) | BP3: CBO Baseline Budget, March 2012: Debt Held by the Public (FY, Bil.$) | BQ3: CBO Baseline Budget, August 2012: Debt Held by the Public (FY, Bil.$) | BR3: CBO Baseline Budget, February 2013: Debt Held by the Public (FY, Bil.$) | BS3: CBO Baseline Budget, May 2013: Debt Held by the Public (FY, Bil.$) | BT3: CBO Baseline Budget, February 2014: Debt Held by the Public (FY, Bil.$) | BU3: CBO Baseline Budget, April 2014: Debt Held by the Public (FY, Bil.$) | BV3: CBO Baseline Budget, August 2014: Debt Held by the Public (FY, Bil.$) | BW3: CBO Baseline Budget, January 2015: Debt Held by the Public (FY, Bil.$) | BX3: CBO Baseline Budget, March 2015: Debt Held by the Public (FY, Bil.$) | BY3: CBO Baseline Budget, August 2015: Debt Held by the Public (FY, Bil.$) | BZ3: CBO Baseline Budget, January 2016: Debt Held by the Public (FY, Bil.$) | CA3: CBO Baseline Budget, March 2016: Debt Held by the Public (FY, Bil.$) | CB3: CBO Baseline Budget, August 2016: Debt Held by the Public (FY, Bil.$) | CC3: CBO Baseline Budget, January 2017: Debt Held by the Public (FY, Bil. US$) | CD3: CBO Baseline Budget, June 2017: Debt Held by the Public (FY, Bil. US$) | CE3: CBO Baseline Budget, April 2018: Debt Held by the Public (FY, Bil. US$) | CF3: CBO Baseline Budget, January 2019: Debt Held by the Public (FY, Bil. US$) | CG3: CBO Baseline Budget, May 2019: Debt Held by the Public (FY, Bil. US$) | CH3: CBO Baseline Budget, August 2019: Debt Held by the Public (FY, Bil. US$) | CI3: CBO Baseline Budget, Jan 2020: Debt Held by the Public (FY, Bil. US$) | CJ3: CBO Baseline Budget, March 2020: Debt Held by the Public (FY, Bil. US$) | CK3: CBO Baseline Budget, Sept 2020: Debt Held by the Public (FY, Bil. US$) | CL3: CBO Baseline Budget, Feb 2021: Debt Held by the Public (FY, Bil. US$) | CM3: CBO Baseline Budget, Jul 2021: Debt Held by the Public (FY, Bil. US$) | CN3: CBO Baseline Budget, May 2022: Debt Held by the Public (FY, Bil. US$) | CO3: CBO Baseline Budget, Feb 2023: Debt Held by the Public (FY, Bil. US$) | CP3: CBO Baseline Budget, May 2023: Debt Held by the Public (FY, Bil. US$) | CQ3: CBO Baseline Budget, Feb 2024: Debt Held by the Public (FY, Bil. US$) | CR3: CBO Baseline Budget, Jun 2024: Debt Held by the Public (FY, Bil. US$) | CS3: CBO Baseline Budget Projections, Debt Held by the Public (Fiscal Yr, Bil.$)
